Workbook

Sheet ITEM MASTER
A1: Sl No | B1: Item Code | C1: Item Name (DRC) | D1: Brand Name | E1: Status | F1: Dosage Form | G1: Strength / Composition | H1: Pack Size / Presentation | I1: Route of Admin | J1: Indications (Summary) | K1: Posology / Dosage | L1: Product Group | M1: Division | N1: Supplier Name 1 | O1: Supplier Name 2 | P1: Supplier Name 3 | Q1: Supplier Name 4 | R1: Supplier Name 5 | S1: Key Market Position in DRC | T1: Demand Drivers | U1: Main Risks / Notes | V1: Overall Strength in DRC
A2: 1 | B2: FG02165 | C2: NEUROQUE 500MCG/ML (MECOBALAMIN) INJ. B/5 AMP | D2: Neuroque | E2: Active | F2: Injection | G2: Methylcobalamin 500 mcg/mL | H2: Box of 5 ampoules of 1 mL | I2: IM / IV | J2: Peripheral & diabetic neuropathies, neurotransmitter synthesis, megaloblastic anemia | K2: 1 ampoule (500 mcg) daily, 3 times per week | L2: UNIQUE A | M2: Marketing | N2: {=IFERROR(INDEX(_xlfn.UNIQUE(_xlfn._xlws.FILTER([1]Sheet1!$W:$W,[1]Sheet1!$H:$H=B2)),1),"")} | O2: {=IFERROR(INDEX(_xlfn.UNIQUE(_xlfn._xlws.FILTER([1]Sheet1!$W:$W,[1]Sheet1!$H:$H=B2)),2),"")} | P2: {=IFERROR(INDEX(_xlfn.UNIQUE(_xlfn._xlws.FILTER([1]Sheet1!$W:$W,[1]Sheet1!$H:$H=B2)),3),"")} | Q2: {=IFERROR(INDEX(_xlfn.UNIQUE(_xlfn._xlws.FILTER([1]Sheet1!$W:$W,[1]Sheet1!$H:$H=B2)),4),"")} | R2: {=IFERROR(INDEX(_xlfn.UNIQUE(_xlfn._xlws.FILTER([1]Sheet1!$W:$W,[1]Sheet1!$H:$H=B2)),5),"")}
A3: 2 | B3: FG02596 | C3: PREGATAS-ME (PREGABALIN+MECOBALAMIN) B/30CAP | D3: Pregatas | E3: Active | F3: Capsule | G3: Pregabalin 75 mg + Methylcobalamin 750 mcg | H3: Box of 30 capsules | I3: Oral | J3: Nerve pain (diabetic neuropathy, shingles, spinal cord injury, fibromyalgia) | K3: As directed by physician | L3: UNIQUE CARDIAC | M3: Marketing | N3: Intas Pharmaceuticals | O3: Indasi Lifescience Pvt Ltd
A4: 3 | B4: FG02595 | C4: PREGATAS-75 (PREGABALIN) B/30 CAPSULE | D4: Pregatas | E4: Active | F4: Capsule | G4: Pregabalin 75 mg | H4: Box of 30 capsules | I4: Oral | J4: Nerve pain (diabetic neuropathy, shingles, spinal cord injury, fibromyalgia) | K4: As directed by physician | L4: UNIQUE CARDIAC | M4: Marketing | N4: Intas Pharmaceuticals
A5: 4 | B5: FG04282 | C5: CYPROPLEX (CYPROHEPTADINE) SIROP 200ML | D5: Cyproplex | E5: Active | F5: Oral Suspension | G5: Cyproheptadine 2 mg / 5 mL | H5: Box of 200 mL | I5: Oral | J5: Allergy symptoms (watery eyes, runny nose, hives, itching) | K5: As directed by physician | L5: OTC PRODUCTS | M5: OTC PRODUCTS | N5: Biomatrix Healthcare Pvt Ltd
A6: 5 | B6: FG04621 | C6: CYPROPLEX-4 (CYPROHEPTADINE) B/ 10 X 10 CES | D6: Cyproplex | E6: Active | F6: Tablet | G6: Cyproheptadine 4 mg | H6: Box of 2×10 & 10×10 tablets | I6: Oral | J6: Allergy symptoms & appetite stimulation | K6: As directed by physician | L6: OTC PRODUCTS | M6: OTC PRODUCTS | N6: Biomatrix Healthcare Pvt Ltd
A7: 6 | B7: FG01016 | C7: DESLORA 2.5MG/5ML (DESLORATADINE) SIROP 60ML | D7: Deslora | E7: Active | F7: Syrup | G7: Desloratadine 2.5 mg / 5 mL | H7: Box of 60 mL (Pineapple flavour) | I7: Oral | J7: Allergies (sneezing, watery eyes, itching), chronic skin hives | K7: <1yr: 2mL; 1-3yr: 2.5mL; 3-6yr: 5mL once daily | L7: UNIQUE A | M7: Marketing | N7: Lincoln Pharmaceuticlas Ltd
A8: 7 | B8: FG01017 | C8: DESLORA-5MG (DESLORATADINE) B/10CES | D8: Deslora | E8: Active | F8: Tablet | G8: Desloratadine 5 mg | H8: Box of 10 tablets | I8: Oral | J8: Allergies (sneezing, watery eyes, itching), chronic skin hives | K8: 1 tablet daily | L8: UNIQUE A | M8: Marketing | N8: Lincoln Pharmaceuticlas Ltd
A9: 8 | B9: FG01829 | C9: LORANIQE 10MG (LORATADINE) B/10 CES | D9: Loranique | E9: Active | F9: Tablet | G9: Loratadine 10 mg | H9: Box of 10 tablets | I9: Oral | J9: Hay fever, allergies (sneezing, runny nose, itchy eyes), hives | K9: 1 tablet daily | L9: VITES | M9: Marketing | N9: Lincoln Pharmaceuticlas Ltd
A10: 9 | B10: FG03625 | C10: BROMOVAN (BROMHEXINE) 4MG /5ML SIRUP 100ML | D10: Bromovan | E10: Active | F10: Syrup | G10: Bromhexine 4 mg / 5 mL | H10: 100 mL bottle | I10: Oral | J10: Respiratory disorders with excessive mucus (bronchitis, bronchiectasis, pneumoconiosis) | K10: Adults/12+: 10mL TID; 6-12y: 5mL TID; 2-5y: 2.5mL TID | L10: OTC PRODUCTS | M10: OTC PRODUCTS | N10: Biomatrix Healthcare Pvt Ltd
A11: 10 | B11: FG01041 | C11: DEXOL (CONTRE LA GRIPPE) SUSP.FL/ 100ML | D11: Dexol | E11: Active | F11: Syrup (per 5mL) | G11: Paracetamol 250mg + Dextromethorphan 10mg + Chlorphenamine 2mg + Phenylephrine 5mg | H11: 100 mL bottle | I11: Oral | J11: Cold/flu symptoms (fever, cough, stuffy nose, body aches) | K11: 1–2 teaspoon (5–10mL) three times daily | L11: OTC PRODUCTS | M11: OTC PRODUCTS | N11: Lincoln Pharmaceuticlas Ltd
A12: 11 | B12: FG01040 | C12: DEXOL (ANTIGRIPPALES) B/10 CAPSULES | D12: Dexol | E12: Active | F12: Capsule | G12: Paracetamol 500mg + Dextromethorphan 15mg + Chlorphenamine 2mg + Phenylephrine 10mg | H12: Box of 10 capsules | I12: Oral | J12: Cold/flu, sinusitis, bronchitis (cough, fever, stuffy nose) | K12: 1 capsule twice daily (adults & children ≥12y) | L12: OTC PRODUCTS | M12: OTC PRODUCTS | N12: Lincoln Pharmaceuticlas Ltd
A13: 12 | B13: FG02669 | C13: QLINDA GEL (CLINDAMYCINE) T/30G | D13: Qlinda | E13: Active | F13: Gel (Topical) | G13: Clindamycin 1% w/w | H13: Tube of 30g & 60g | I13: Cutaneous | J13: Acne treatment | K13: Apply to clean, dry skin twice daily | L13: OTC PRODUCTS | M13: OTC PRODUCTS
A14: 13 | B14: FG04094 | C14: TOPISOL (CLOBETASOL) CREME T/30G | D14: Topisol | E14: Active | F14: Cream (Topical) | G14: Clobetasol 0.05% w/w | H14: Tube of 30g | I14: Topical | J14: Eczema, contact dermatitis, seborrheic dermatitis, psoriasis | K14: Apply 1–2 times daily | L14: OTC PRODUCTS | M14: OTC PRODUCTS
A15: 14 | B15: FG04795 | C15: TOPISOL (CLOBETASOL) CREME T/15G | D15: Topisol | E15: Active | F15: Cream (Topical) | G15: Clobetasol 0.05% w/w | H15: Tube of 15g | I15: Topical | J15: Eczema, contact dermatitis, seborrheic dermatitis, psoriasis | K15: Apply 1–2 times daily | L15: OTC PRODUCTS | M15: OTC PRODUCTS
A16: 15 | B16: FG00518 | C16: BUCCODRIL (BAIN DE BOUCHE) SOLUTION FL/150ML | D16: Buccodril | E16: Active | F16: Mouthwash Solution | G16: Thymol 0.06% + Eucalyptol 0.09% + Menthol 0.04% + Ethanol 21.6% | H16: Bottle of 150 mL | I16: Oral (Rinse) | J16: Dental plaque prevention, gingivitis, oral hygiene | K16: Rinse with 10 mL twice daily (spit out) | L16: UNIQUE A | M16: Marketing | N16: Biomatrix Healthcare Pvt Ltd
A17: 16 | B17: FG01439 | C17: FUSIDIQ (ACIDE FUSIDIQUE) CREME T/15G | D17: Fusidiq | E17: Active | F17: Cream (Topical) | G17: Fusidic acid 2% w/w | H17: Tube (topical) | I17: Topical | J17: Bacterial skin infections (cellulitis, impetigo, conjunctivitis) | K17: As directed by physician | L17: VITES | M17: Marketing | N17: Biomatrix Healthcare Pvt Ltd
A18: 17 | B18: FG03406 | C18: UNIDERM @@ 30MG @@ CREAM | D18: Uniderm | E18: Active | F18: Cream (Topical) | G18: Betamethasone valerate 0.61mg + Gentamicin 1mg + Tolnaftate 10mg + Clioquinol 10mg | H18: Tubes of 15g & 30g | I18: Topical | J18: Skin fungal infections | K18: Apply 1–2 times daily | L18: OTC PRODUCTS | M18: OTC PRODUCTS | N18: Lincoln Pharmaceuticlas Ltd
A19: 18 | B19: FG08529 | C19: KORTIF (HYDROCORTISONE 100 MG) TUBE DE 15G | D19: Kortif | E19: Active | F19: Cream (Topical) | G19: Hydrocortisone (active ingredient) | H19: Tube (topical) | I19: Topical | J19: Swelling, itching, irritation (insect bites, eczema, dermatitis, anal itching) | K19: Apply 1–2 times daily | L19: OTC PRODUCTS | M19: OTC PRODUCTS | N19: Scott Edil Pharmacia Ltd
A20: 19 | B20: FG01694 | C20: KETOMIZ (KETOCONAZOLE) SHAMPOO 100ML | D20: Ketomiz | E20: Active | F20: Shampoo | G20: Ketoconazole 2% w/v | H20: Bottle of 100 mL | I20: Topical (Scalp) | J20: Fungal infections (tinea, candidiasis, dandruff, seborrheic dermatitis) | K20: As directed by physician | L20: OTC PRODUCTS | M20: OTC PRODUCTS | N20: Biomatrix Healthcare Pvt Ltd
A21: 20 | B21: FG03624 | C21: LE BOXEUR (ANTI-MOSQUITO) POMMADE 10GR | D21: Boxer | E21: Active | F21: Balm (Topical) | G21: Natural extracts (camphor, mint, etc.) | H21: 10 g balm (green) | I21: Topical | J21: Antipruritic, analgesic, mosquito repellent, colds, headache, muscle aches | K21: Rub gently on affected skin 2–3 times daily | L21: OTC PRODUCTS | M21: OTC PRODUCTS | N21: Yiwu Royal
A22: 21 | B22: FG04828 | C22: LE BOXEUR (ANTI-MOSQUITO) LIQUID 3.5ML | D22: Boxer | E22: Active | F22: Liquid | G22: Natural extracts (camphor, mint, etc.) | H22: 3.5 mL bottle | I22: Oral / External | J22: Antipruritic, analgesic, mosquito repellent, colds, headache, muscle aches | K22: As directed by physician | L22: OTC PRODUCTS | M22: OTC PRODUCTS | N22: Yiwu Royal
A23: 22 | B23: FG04589 | C23: BENZOATE DE BENZYLE (BENZOSOL) 25% 100ML | D23: Benzosol | E23: Active | F23: Topical Solution | G23: Benzyl Benzoate 25% w/v | H23: Bottle of 100 mL | I23: Topical | J23: Scabies (Sarcoptes scabiei), trombidiosis (chiggers) | L23: OTC PRODUCTS | M23: OTC PRODUCTS | N23: Biomatrix Healthcare Pvt Ltd
A24: 23 | B24: FG01000 | C24: DERMACIDAL (ANTISEPSIE) SOLUTION 125ML | D24: Dermacidal | E24: Active | F24: Solution (Skin) | G24: Benzalkonium chloride 0.5g + Chlorhexidine digluconate 0.2g per 100ml | H24: Bottle of 125ml | I24: Topical (Skin) | J24: Antiseptic for external skin infections; cleansing of cutaneous/mucous affections | K24: Apply minimum twice daily | L24: UNIQUE A | M24: Marketing | N24: Biomatrix Healthcare Pvt Ltd
A25: 24 | B25: FG04728 | C25: GERMITTOL 50ML LIQUID | D25: Germittol | E25: Active | F25: Solution | G25: Chloroxylenol 4.8% + Terpineol 9.0% + Alcohol 13.1% | H25: Bottles of 50ml & 100ml | I25: Topical (External) | J25: Antiseptic for external skin infections | K25: Apply minimum twice daily | L25: OTC PRODUCTS | M25: OTC PRODUCTS | N25: Biomatrix Healthcare Pvt Ltd
A26: 25 | B26: FG03425 | C26: V-LAVAGE (ACIDE LACTIQUE) LIQUIDE DE LAVAGE 100ML | D26: V-Lavage | E26: Active | F26: Vaginal Wash Solution | G26: Lactic acid 1.2% + Sea buckthorn oil + Tea tree oil (pH 3.5) | H26: Bottle of 100ml | I26: Vaginal | J26: Antiseptic solution for vaginal care | K26: Apply minimum twice daily | L26: UNIQUE A | M26: Marketing | N26: Biomatrix Healthcare Pvt Ltd
A27: 26 | B27: FG01403 | C27: FOREDERM ( BETAMETHASONE DIPROPIONATE) CREME 15G | D27: Forederm | E27: Active | F27: Cream (Topical) | G27: Betamethasone dipropionate 0.05% | H27: Tubes of 15g & 30g | I27: Topical | J27: Eczema, dermatitis, allergies, rash (reduces swelling, itching, redness) | K27: Apply minimum twice daily | L27: UNIQUE GENERIC | M27: Generic
A28: 27 | B28: FG03410 | C28: UNIDINE-M (POVIDONE IODE+ METRO) POMMDE 30G | D28: Unidine | E28: Active | F28: Ointment | G28: Povidone Iodized 5% + Metronidazole 1% | H28: Box of 30g ointment | I28: Topical | J28: Broad-spectrum for wounds, traumatic tears, ulcers, cellulitis, bedsores | K28: Apply minimum twice daily | L28: VITES | M28: Marketing | N28: Lincoln Pharmaceuticlas Ltd
A29: 28 | B29: FG03408 | C29: UNIDINE (POVIDONE IODEE) 10% SOLUTION 125 ML | D29: Unidine | E29: Active | F29: Solution | G29: Povidone Iodized 10% | H29: Bottle of 125ml | I29: Topical | J29: Skin antisepsis, operative field, wounds, burns, vaginitis | K29: Apply minimum twice daily | L29: VITES | M29: Marketing | N29: Hind Pharma Aag
A30: 29 | B30: FG03409 | C30: UNIDINE (POVIDONE-IODEE) 5% POMMADE 20G | D30: Unidine | E30: Active | F30: Ointment | G30: Povidone Iodized 5% | H30: Tube of 20g | I30: Topical | J30: Antiseptic for skin disinfection, minor wounds | K30: Apply minimum twice daily | L30: VITES | M30: Marketing | N30: Biomatrix Healthcare Pvt Ltd
A31: 30 | B31: FG00551 | C31: CALMIN (CALAMINE) LOTION 100ML | D31: Calmin Lotion | E31: Active | F31: Lotion | G31: Calamine 8% + Aloe Vera 10% + Light Liquid Paraffin 10% | H31: Bottle of 100ml | I31: Topical | J31: Mild itchiness (sunburn, insect bites, poison ivy, mild skin conditions) | K31: Apply minimum twice daily | L31: VITES | M31: Marketing | N31: Biomatrix Healthcare Pvt Ltd
A32: 31 | B32: FG04836 | C32: CLOTRISAN V6 (CLOTRIMAZOLE) B/6 OVULE+APPLOCATOR | D32: Clotrisan | E32: Active | F32: Vaginal Insert / Ovule | G32: Clotrimazole 1% w/w | H32: Box of 6 ovules | I32: Vaginal | J32: Vaginal candidiasis, trichomoniasis, mixed vaginal infections, bacterial vaginitis | K32: 1 insert deeply into vagina each evening for 6 consecutive nights | L32: OTC PRODUCTS | M32: OTC PRODUCTS | N32: Biomatrix Healthcare Pvt Ltd
A33: 32 | B33: FG04615 | C33: CLOTRISAN (CLOTRIMAZOLE) POUDRE 50G | D33: Clotrisan | E33: Active | F33: Topical Powder | G33: Clotrimazole 1% + Zinc Oxide 1.75% + Dimeticone 2.5% + Talc | H33: Bottle of 50g | I33: Topical | J33: Antifungal for skin infections / rashes | K33: As directed by physician | L33: OTC PRODUCTS | M33: OTC PRODUCTS | N33: Biomatrix Healthcare Pvt Ltd
A34: 33 | B34: FG00865 | C34: CONVEX PRESERVATIF LISSE B/3PCS | D34: Convex | E34: Active | F34: Condom (Medical Device) | G34: N/A | H34: Box of 3 condoms | I34: Barrier / External | J34: Reduces probability of pregnancy or sexually transmitted infections (STIs) | K34: Single use during intercourse; use as directed | L34: UNIQUE SERGICAL | M34: Generic
A35: 34 | B35: FG04792 | C35: TADANIQUE 20MG (TADALAFIL) B/4CES | D35: Tadanique | E35: Active | F35: Tablet | G35: Tadalafil 20 mg | H35: Box of 4 tablets | I35: Oral | J35: Erectile dysfunction (ED), Benign prostatic hyperplasia (BPH), Pulmonary arterial hypertension | K35: 1 tablet once daily, 45 mins to 1 hour before relation | L35: UNIQUE GENERIC | M35: Generic
A36: 35 | B36: FG04089 | C36: SILDEQUE-100MG (SILDENAFIL) B/4CES | D36: Sildeque | E36: Active | F36: Tablet | G36: Sildenafil 100 mg | H36: Box of 4 tablets | I36: Oral | J36: Erectile dysfunction, Pulmonary arterial hypertension | K36: 1 tablet once daily, 45 mins to 1 hour before relation | L36: OTC PRODUCTS | M36: OTC PRODUCTS | N36: Lincoln Pharmaceuticlas Ltd | O36: Sunrise Remedies Pvt Ltd
A37: 36 | B37: FG04090 | C37: SILDEQUE-50 MG (SILDENAFIL) B/4 CES | D37: Sildeque | E37: Active | F37: Tablet | G37: Sildenafil 50 mg | H37: Box of 4 tablets | I37: Oral | J37: Erectile dysfunction, Pulmonary arterial hypertension | L37: OTC PRODUCTS | M37: OTC PRODUCTS | N37: Sunrise Remedies Pvt Ltd
A38: 37 | B38: FG03412 | C38: UNISPA 10MG (BUSCOPAN) B/ 6 SUPPO | D38: Unispa | E38: Active | F38: Suppository | G38: Hyoscine Butylbromide 10 mg | H38: Box of 6 suppositories | I38: Rectal | J38: Crampy abdominal pain, esophageal spasms, renal colic, bladder spasms | K38: As directed by physician | L38: UNIQUE A | M38: Marketing
A39: 38 | B39: FG03070 | C39: SPARET (MEFENAMIQUE + DICYCLOVIRINE) B/10CES | D39: Sparet | E39: Active | F39: Tablet | G39: Mefenamic Acid 500 mg + Paracetamol 325 mg | H39: Box of 10 tablets | I39: Oral | J39: Joint and muscle pains (adults) | K39: 1 tablet once or twice daily | L39: UNIQUE A | M39: Marketing
A40: 39 | B40: FG03069 | C40: SPARET (DICYCLOVERINE+SIMETICONE) GOUTTES 15ML | D40: Sparet | E40: Active | F40: Oral Drops | G40: Simeticone 40 mg + Dicycloverine 10 mg (per drop) | H40: 15 mL oral drops bottle | I40: Oral | J40: Colicky pain in children | K40: 1 drop/kg/dose, 2–3 times daily | L40: UNIQUE A | M40: Marketing | N40: Lincoln Pharmaceuticlas Ltd
...

Sheet Sheet1
A1: Category | B1: Item Group | C1: Item Code | D1: Item Name | E1: Supplier Name | F1: Import Item Name | G1: Created By | H1: Purchase Unit | I1: Pack Size | J1: Std/Sales Unit | K1: Shipping Packsize | L1: Pack Weight (kg) | M1: HTS Code | N1: HTS Description | O1: Duty (%) | P1: Active
A2: FINISHED GOODS | B2: GENERAL | C2: FG00001 | D2: *****CLIFA-600MG UPS B/20CES | E2: NA | F2: *****CLIFA-600MG UPS B/20CES | G2: admin | H2: PCS | I2: 1 | J2: PCS | K2: 1 | M2: NA | N2: NA | P2: Yes | Q2: =VLOOKUP(C2,'ITEM MASTER'!B:B,1,0) -> FG00001 | R2: =VLOOKUP(B2,'ITEM MASTER'!L:M,2,0) -> Generic
A3: FINISHED GOODS | B3: GENERAL | C3: FG00003 | D3: 3FORT (VIT-B1.B6.B12) SIROP 100ML | E3: UNIQUE VENTURES LTD | F3: 3FORT (VIT-B1.B6.B12) SIROP 100ML | G3: admin | H3: PCS | I3: 1 | J3: PCS | K3: 1 | M3: NA | N3: NA | P3: Yes | Q3: =VLOOKUP(C3,'ITEM MASTER'!B:B,1,0) -> FG00003 | R3: =VLOOKUP(B3,'ITEM MASTER'!L:M,2,0) -> Generic
A4: FINISHED GOODS | B4: GENERAL | C4: FG00004 | D4: 3FORT @@ Z @@@ B/30CES | E4: NA | F4: 3FORT @@ Z @@@ B/30CES | G4: admin | H4: PCS | I4: 1 | J4: PCS | K4: 1 | M4: NA | N4: NA | P4: Yes | Q4: =VLOOKUP(C4,'ITEM MASTER'!B:B,1,0) -> FG00004 | R4: =VLOOKUP(B4,'ITEM MASTER'!L:M,2,0) -> Generic
A5: FINISHED GOODS | B5: GENERAL | C5: FG00005 | D5: 3FORT B/30CES | E5: NA | F5: 3FORT B/30CES | G5: admin | H5: PCS | I5: 1 | J5: PCS | K5: 1 | M5: NA | N5: NA | P5: Yes | Q5: =VLOOKUP(C5,'ITEM MASTER'!B:B,1,0) -> FG00005 | R5: =VLOOKUP(B5,'ITEM MASTER'!L:M,2,0) -> Generic
A6: FINISHED GOODS | B6: GENERAL | C6: FG00006 | D6: 3FORT-Z ( VIT B1+B6+B12) ZINC SIROP 100ML | E6: NA | F6: 3FORT-Z ( VIT B1+B6+B12) ZINC SIROP 100ML | G6: admin | H6: PCS | I6: 1 | J6: PCS | K6: 1 | M6: NA | N6: NA | P6: No | Q6: =VLOOKUP(C6,'ITEM MASTER'!B:B,1,0) -> FG00006 | R6: =VLOOKUP(B6,'ITEM MASTER'!L:M,2,0) -> Generic
A7: FINISHED GOODS | B7: GENERAL | C7: FG00007 | D7: 3VIT FORT 10AMP | E7: NA | F7: 3VIT FORT 10AMP | G7: admin | H7: PCS | I7: 1 | J7: PCS | K7: 1 | M7: NA | N7: NA | P7: Yes | Q7: =VLOOKUP(C7,'ITEM MASTER'!B:B,1,0) -> FG00007 | R7: =VLOOKUP(B7,'ITEM MASTER'!L:M,2,0) -> Generic
A8: FINISHED GOODS | B8: GENERAL | C8: FG00009 | D8: A-DEM CREME 15MG | E8: NA | F8: A-DEM CREME 15MG | G8: admin | H8: PCS | I8: 1 | J8: PCS | K8: 1 | M8: NA | N8: NA | P8: Yes | Q8: =VLOOKUP(C8,'ITEM MASTER'!B:B,1,0) -> FG00009 | R8: =VLOOKUP(B8,'ITEM MASTER'!L:M,2,0) -> Generic
A9: FINISHED GOODS | B9: GENERAL | C9: FG00010 | D9: A-DEM CREME 30MG | E9: NA | F9: A-DEM CREME 30MG | G9: admin | H9: PCS | I9: 1 | J9: PCS | K9: 1 | M9: NA | N9: NA | P9: Yes | Q9: =VLOOKUP(C9,'ITEM MASTER'!B:B,1,0) -> FG00010 | R9: =VLOOKUP(B9,'ITEM MASTER'!L:M,2,0) -> Generic
A10: FINISHED GOODS | B10: GENERAL | C10: FG00011 | D10: A-DEM FEMINA | E10: NA | F10: A-DEM FEMINA | G10: admin | H10: PCS | I10: 1 | J10: PCS | K10: 1 | M10: NA | N10: NA | P10: Yes | Q10: =VLOOKUP(C10,'ITEM MASTER'!B:B,1,0) -> FG00011 | R10: =VLOOKUP(B10,'ITEM MASTER'!L:M,2,0) -> Generic
A11: FINISHED GOODS | B11: GENERAL | C11: FG00012 | D11: A-DEM POUDRE 100MG | E11: NA | F11: A-DEM POUDRE 100MG | G11: admin | H11: PCS | I11: 1 | J11: PCS | K11: 1 | M11: NA | N11: NA | P11: Yes | Q11: =VLOOKUP(C11,'ITEM MASTER'!B:B,1,0) -> FG00012 | R11: =VLOOKUP(B11,'ITEM MASTER'!L:M,2,0) -> Generic
A12: FINISHED GOODS | B12: GENERAL | C12: FG00013 | D12: A-DEM SOAP 75MG | E12: NA | F12: A-DEM SOAP 75MG | G12: admin | H12: PCS | I12: 1 | J12: PCS | K12: 1 | M12: NA | N12: NA | P12: Yes | Q12: =VLOOKUP(C12,'ITEM MASTER'!B:B,1,0) -> FG00013 | R12: =VLOOKUP(B12,'ITEM MASTER'!L:M,2,0) -> Generic
A13: FINISHED GOODS | B13: GENERAL | C13: FG00015 | D13: ABAISSE LANGUE | E13: NA | F13: ABAISSE LANGUE | G13: admin | H13: PCS | I13: 1 | J13: PCS | K13: 1 | M13: NA | N13: NA | P13: Yes | Q13: =VLOOKUP(C13,'ITEM MASTER'!B:B,1,0) -> FG00015 | R13: =VLOOKUP(B13,'ITEM MASTER'!L:M,2,0) -> Generic
... A9386: FINISHED GOODS | B9386: SPECIALITIES | C9386: FG05696 | D9386: VOLTARENE 75MG 5AMP (GR) | E9386: NA | F9386: VOLTARENE 75MG 5AMP (GR) | G9386: UNIQUE1 | H9386: PCS | I9386: 1 | J9386: PCS | K9386: 1 | M9386: NA | N9386: NA | P9386: Yes | Q9386: =VLOOKUP(C9386,'ITEM MASTER'!B:B,1,0) -> FG05696 | R9386: =VLOOKUP(B9386,'ITEM MASTER'!L:M,2,0) -> Generic
Q9387: =VLOOKUP(C9387,'ITEM MASTER'!B:B,1,0) -> #N/A | R9387: =VLOOKUP(B9387,'ITEM MASTER'!L:M,2,0) -> #N/A
