Workbook

Sheet Data
A1: Company | B1: PRF_No | C1: PRF_Date | D1: PRF_Location | E1: PRF_Qty | F1: Pack_Size | G1: Conversion_Unit | H1: PRF_Qty_Converted | I1: PO_No | J1: PO_Date | K1: PO_Qty | L1: PO_Rate | M1: PO_Net_Amount | N1: PO_Other_Charge_Percent | O1: PO_Other_Charge_Amount | P1: PO_Total_Amount | Q1: PI_No | R1: PI_Date | S1: Supplier_Name | T1: Item_Code | U1: Product_Name_(DRC) | V1: PI_Qty | W1: PI_FOC_Qty | X1: PI_Rate | Y1: PI_Net_Amount | Z1: PI_Other_Charge_Amount | AA1: PI_Total_Amount | AB1: Advance_Percent | AC1: Advance_Amount | AD1: Advance_Amount_Paid | AE1: Advance_Paid_Date | AF1: Advance_SWIFT_No | AG1: Dispatched_Qty | AH1: Invoice_Qty | AI1: FOC_QTY | AJ1: Short_Excess_Qty | AK1: Invoice_No | AL1: Invoice_Date | AM1: Invoice_Company | AN1: Invoice_Rate | AO1: Invoice_Amount | AP1: Freight | AQ1: Insurance | AR1: Other_Charges | AS1: Invoice_Total_Amount | AT1: BL_No | AU1: BL_Date | AV1: Shipment_Status | AW1: GRN_Qty | AX1: GRN_No | AY1: GRN_Date | AZ1: Prev_Advance_Adjusted | BA1: Available_Advance | BB1: Running_PO_Advance_Used | BC1: Extra_Short_Amount_Used | BD1: Total_Advance_Deducted | BE1: Remaining_Advance | BF1: Advance_Adjusted | BG1: Final_Advance_Remaining | BH1: Final_Payable_Balance | BI1: Balance_Paid_Part1 | BJ1: Balance_Paid_Date_Part1 | BK1: Part1_SWIFT_No | BL1: Balance_Paid_Part2 | BM1: Part2_SWIFT_No | BN1: Balance_Paid_Date_Part2 | BO1: Final_Paid_Total | BP1: Final_Outstanding | BQ1: Payment_Status | BR1: Remarks | BS1: PO_Status | BT1: PO_Age_Days
A2: Aizah Pharma FZCO | B2: 1932.26 | C2: 46188 | D2: Kinshasa | E2: 15000 | F2: 10 ml x 20 Amps | G2: =IF(AG2="","GRN Not Received",AW2/AG2) -> GRN Not Received | H2: =IF(E2="PRF_Details_Not Availbale","PRF Qty Not Available",IF(G2="GRN Not Received","GRN Not Received",--E2*--G2)) -> GRN Not Received | I2: 0131/2026 | J2: 46197 | K2: 300000 | L2: 0.13 | M2: =K2*L2 -> 39000 | N2: 0 | O2: 0 | P2: =M2+O2 -> 39000 | Q2: AFPL/PI/313 | R2: 46197 | S2: Aarmed Formulations Pvt Ltd | T2: NEW 001 | U2: =IFERROR(VLOOKUP(T2,'item master'!B:C,2,0),"") -> DYNAMIQ20 AMP | V2: 300000 | W2: 0 | X2: 0.13 | Y2: =V2*X2 -> 39000 | Z2: 0 | AA2: =Y2+Z2 -> 39000 | AB2: 0.3 | AC2: =Y2*AB2 -> 11700 | AD2: 11700 | AE2: 46203 | AF2: 033DBFC261801579 | AH2: =AG2 -> 0 | AJ2: =V2-AG2 -> 300000 | AS2: =AO2+AP2+AQ2+AR2 -> 0 | AV2: PO Issued – Awaiting BL | BA2: =AD2+AZ2 -> 11700 | BB2: 0 | BC2: 0 | BD2: =IF(AK2>0,BA2+BB2+BC2,"0") -> 0 | BE2: =BA2-BD2 -> 11700 | BF2: 0 | BG2: =BE2-BF2 -> 11700 | BH2: =AS2-BD2 -> 0 | BO2: =BI2+BL2 -> 0 | BP2: =BH2-BO2 -> 0 | BQ2: =IF(ROUND(BG2,2)>0,"Advance With Supplier",IF(ROUND(BP2,2)>0,"Payable Balance Supplier","Fully Paid")) -> Advance With Supplier | BS2: =IF(AX2<>"","Closed","Open") -> Open | BT2: =IF(BS2="Open",TODAY()-J2,"Closed") -> 66
A3: Aizah Pharma FZCO | B3: 1904.26 | C3: 46174 | D3: Kinshasa | E3: 24000 | F3: 125 gm | G3: =IF(AG3="","GRN Not Received",AW3/AG3) -> GRN Not Received | H3: =IF(E3="PRF_Details_Not Availbale","PRF Qty Not Available",IF(G3="GRN Not Received","GRN Not Received",--E3*--G3)) -> GRN Not Received | I3: 0121/2026 | J3: 46211 | K3: =E3 -> 24000 | L3: 0.28 | M3: =K3*L3 -> 6720 | N3: 0 | O3: 0 | P3: =M3+O3 -> 6720 | Q3: 2062026 | R3: 46175 | S3: Kavit Soap Industries | T3: FG08036 | U3: =IFERROR(VLOOKUP(T3,'item master'!B:C,2,0),"") -> DELABACT SAVON ***125GM*** | V3: 24000 | W3: 0 | X3: 0.28 | Y3: =V3*X3 -> 6720 | Z3: 0 | AA3: =Y3+Z3 -> 6720 | AB3: 0.5 | AC3: =Y3*AB3 -> 3360 | AD3: =AC3 -> 3360 | AE3: 46216 | AF3: 033DBFC261920624 | AH3: =AG3 -> 0 | AJ3: =V3-AG3 -> 24000 | AS3: =AO3+AP3+AQ3+AR3 -> 0 | AV3: PO Issued – Awaiting BL | BA3: =AD3+AZ3 -> 3360 | BB3: 0 | BC3: 0 | BD3: =IF(AK3>0,BA3+BB3+BC3,"0") -> 0 | BE3: =BA3-BD3 -> 3360 | BF3: 0 | BG3: =BE3-BF3 -> 3360 | BH3: =AS3-BD3 -> 0 | BO3: =BI3+BL3 -> 0 | BP3: =BH3-BO3 -> 0 | BQ3: =IF(ROUND(BG3,2)>0,"Advance With Supplier",IF(ROUND(BP3,2)>0,"Payable Balance Supplier","Fully Paid")) -> Advance With Supplier | BS3: =IF(AX3<>"","Closed","Open") -> Open | BT3: =IF(BS3="Open",TODAY()-J3,"Closed") -> 52
A4: Aizah Pharma FZCO | B4: 1904.26 | C4: 46174 | D4: Kinshasa | E4: 200000 | F4: 75 gm | G4: =IF(AG4="","GRN Not Received",AW4/AG4) -> GRN Not Received | H4: =IF(E4="PRF_Details_Not Availbale","PRF Qty Not Available",IF(G4="GRN Not Received","GRN Not Received",--E4*--G4)) -> GRN Not Received | I4: 0121/2026 | J4: 46211 | K4: =E4 -> 200000 | L4: 0.2 | M4: =K4*L4 -> 40000 | N4: 0 | O4: 0 | P4: =M4+O4 -> 40000 | Q4: 2062026 | R4: 46175 | S4: Kavit Soap Industries | T4: FG00973 | U4: =IFERROR(VLOOKUP(T4,'item master'!B:C,2,0),"") -> DELABACT SAVON 75GM | V4: 200000 | W4: 0 | X4: 0.2 | Y4: =V4*X4 -> 40000 | Z4: 0 | AA4: =Y4+Z4 -> 40000 | AB4: 0.5 | AC4: =Y4*AB4 -> 20000 | AD4: =AC4 -> 20000 | AE4: 46216 | AF4: 033DBFC261920624 | AH4: =AG4 -> 0 | AJ4: =V4-AG4 -> 200000 | AS4: =AO4+AP4+AQ4+AR4 -> 0 | AV4: PO Issued – Awaiting BL | BA4: =AD4+AZ4 -> 20000 | BB4: 0 | BC4: 0 | BD4: =IF(AK4>0,BA4+BB4+BC4,"0") -> 0 | BE4: =BA4-BD4 -> 20000 | BF4: 0 | BG4: =BE4-BF4 -> 20000 | BH4: =AS4-BD4 -> 0 | BO4: =BI4+BL4 -> 0 | BP4: =BH4-BO4 -> 0 | BQ4: =IF(ROUND(BG4,2)>0,"Advance With Supplier",IF(ROUND(BP4,2)>0,"Payable Balance Supplier","Fully Paid")) -> Advance With Supplier | BS4: =IF(AX4<>"","Closed","Open") -> Open | BT4: =IF(BS4="Open",TODAY()-J4,"Closed") -> 52
A5: Aizah Pharma FZCO | B5: 1904.26 | C5: 46174 | D5: Kinshasa | E5: 12000 | F5: 75 gm | G5: =IF(AG5="","GRN Not Received",AW5/AG5) -> GRN Not Received | H5: =IF(E5="PRF_Details_Not Availbale","PRF Qty Not Available",IF(G5="GRN Not Received","GRN Not Received",--E5*--G5)) -> GRN Not Received | I5: 0121/2026 | J5: 46211 | K5: =E5 -> 12000 | L5: 0.196 | M5: =K5*L5 -> 2352 | N5: 0 | O5: 0 | P5: =M5+O5 -> 2352 | Q5: 2062026 | R5: 46175 | S5: Kavit Soap Industries | T5: FG08549 | U5: =IFERROR(VLOOKUP(T5,'item master'!B:C,2,0),"") -> 20 DEGRE SAVON DE BEAUTE PAPAYE 75G | V5: 12000 | W5: 0 | X5: 0.196 | Y5: =V5*X5 -> 2352 | Z5: 0 | AA5: =Y5+Z5 -> 2352 | AB5: 0.5 | AC5: =Y5*AB5 -> 1176 | AD5: =AC5 -> 1176 | AE5: 46216 | AF5: 033DBFC261920624 | AH5: =AG5 -> 0 | AJ5: =V5-AG5 -> 12000 | AS5: =AO5+AP5+AQ5+AR5 -> 0 | AV5: PO Issued – Awaiting BL | BA5: =AD5+AZ5 -> 1176 | BB5: 0 | BC5: 0 | BD5: =IF(AK5>0,BA5+BB5+BC5,"0") -> 0 | BE5: =BA5-BD5 -> 1176 | BF5: 0 | BG5: =BE5-BF5 -> 1176 | BH5: =AS5-BD5 -> 0 | BO5: =BI5+BL5 -> 0 | BP5: =BH5-BO5 -> 0 | BQ5: =IF(ROUND(BG5,2)>0,"Advance With Supplier",IF(ROUND(BP5,2)>0,"Payable Balance Supplier","Fully Paid")) -> Advance With Supplier | BS5: =IF(AX5<>"","Closed","Open") -> Open | BT5: =IF(BS5="Open",TODAY()-J5,"Closed") -> 52
A6: Aizah Pharma FZCO | B6: 1904.26 | C6: 46174 | D6: Kinshasa | E6: 12000 | F6: 75 gm | G6: =IF(AG6="","GRN Not Received",AW6/AG6) -> GRN Not Received | H6: =IF(E6="PRF_Details_Not Availbale","PRF Qty Not Available",IF(G6="GRN Not Received","GRN Not Received",--E6*--G6)) -> GRN Not Received | I6: 0121/2026 | J6: 46211 | K6: =E6 -> 12000 | L6: 0.28 | M6: =K6*L6 -> 3360 | N6: 0 | O6: 0 | P6: =M6+O6 -> 3360 | Q6: 2062026 | R6: 46175 | S6: Kavit Soap Industries | T6: FG08037 | U6: =IFERROR(VLOOKUP(T6,'item master'!B:C,2,0),"") -> KETOMIZ SAVON 75GM | V6: 12000 | W6: 0 | X6: 0.28 | Y6: =V6*X6 -> 3360 | Z6: 0 | AA6: =Y6+Z6 -> 3360 | AB6: 0.5 | AC6: =Y6*AB6 -> 1680 | AD6: =AC6 -> 1680 | AE6: 46216 | AF6: 033DBFC261920624 | AH6: =AG6 -> 0 | AJ6: =V6-AG6 -> 12000 | AS6: =AO6+AP6+AQ6+AR6 -> 0 | AV6: PO Issued – Awaiting BL | BA6: =AD6+AZ6 -> 1680 | BB6: 0 | BC6: 0 | BD6: =IF(AK6>0,BA6+BB6+BC6,"0") -> 0 | BE6: =BA6-BD6 -> 1680 | BF6: 0 | BG6: =BE6-BF6 -> 1680 | BH6: =AS6-BD6 -> 0 | BO6: =BI6+BL6 -> 0 | BP6: =BH6-BO6 -> 0 | BQ6: =IF(ROUND(BG6,2)>0,"Advance With Supplier",IF(ROUND(BP6,2)>0,"Payable Balance Supplier","Fully Paid")) -> Advance With Supplier | BS6: =IF(AX6<>"","Closed","Open") -> Open | BT6: =IF(BS6="Open",TODAY()-J6,"Closed") -> 52
A7: Aizah Pharma FZCO | B7: 1904.26 | C7: 46174 | D7: Kinshasa | E7: 12000 | F7: 100 gm | G7: =IF(AG7="","GRN Not Received",AW7/AG7) -> GRN Not Received | H7: =IF(E7="PRF_Details_Not Availbale","PRF Qty Not Available",IF(G7="GRN Not Received","GRN Not Received",--E7*--G7)) -> GRN Not Received | I7: 0121/2026 | J7: 46211 | K7: =E7 -> 12000 | L7: 0.276 | M7: =K7*L7 -> 3312 | N7: 0 | O7: 0 | P7: =M7+O7 -> 3312 | Q7: 2062026 | R7: 46175 | S7: Kavit Soap Industries | T7: FG08548 | U7: =IFERROR(VLOOKUP(T7,'item master'!B:C,2,0),"") -> GERMITTOL SAVON 100 GM | V7: 12000 | W7: 0 | X7: 0.276 | Y7: =V7*X7 -> 3312 | Z7: 0 | AA7: =Y7+Z7 -> 3312 | AB7: 0.5 | AC7: =Y7*AB7 -> 1656 | AD7: =AC7 -> 1656 | AE7: 46216 | AF7: 033DBFC261920624 | AH7: =AG7 -> 0 | AJ7: =V7-AG7 -> 12000 | AS7: =AO7+AP7+AQ7+AR7 -> 0 | AV7: PO Issued – Awaiting BL | BA7: =AD7+AZ7 -> 1656 | BB7: 0 | BC7: 0 | BD7: =IF(AK7>0,BA7+BB7+BC7,"0") -> 0 | BE7: =BA7-BD7 -> 1656 | BF7: 0 | BG7: =BE7-BF7 -> 1656 | BH7: =AS7-BD7 -> 0 | BO7: =BI7+BL7 -> 0 | BP7: =BH7-BO7 -> 0 | BQ7: =IF(ROUND(BG7,2)>0,"Advance With Supplier",IF(ROUND(BP7,2)>0,"Payable Balance Supplier","Fully Paid")) -> Advance With Supplier | BS7: =IF(AX7<>"","Closed","Open") -> Open | BT7: =IF(BS7="Open",TODAY()-J7,"Closed") -> 52
A8: Aizah Pharma FZCO | B8: 1904.26 | C8: 46174 | D8: Kinshasa | E8: 30000 | F8: 100 gm | G8: =IF(AG8="","GRN Not Received",AW8/AG8) -> GRN Not Received | H8: =IF(E8="PRF_Details_Not Availbale","PRF Qty Not Available",IF(G8="GRN Not Received","GRN Not Received",--E8*--G8)) -> GRN Not Received | I8: 0121/2026 | J8: 46211 | K8: =E8 -> 30000 | L8: 0.24 | M8: =K8*L8 -> 7200 | N8: 0 | O8: 0 | P8: =M8+O8 -> 7200 | Q8: 2062026 | R8: 46175 | S8: Kavit Soap Industries | T8: FG08555 | U8: =IFERROR(VLOOKUP(T8,'item master'!B:C,2,0),"") -> 20 DEGRE TALC (NEEM+MENTHE) 100G | V8: 30000 | W8: 0 | X8: 0.24 | Y8: =V8*X8 -> 7200 | Z8: 0 | AA8: =Y8+Z8 -> 7200 | AB8: 0.5 | AC8: =Y8*AB8 -> 3600 | AD8: =AC8 -> 3600 | AE8: 46216 | AF8: 033DBFC261920624 | AH8: =AG8 -> 0 | AJ8: =V8-AG8 -> 30000 | AS8: =AO8+AP8+AQ8+AR8 -> 0 | AV8: PO Issued – Awaiting BL | BA8: =AD8+AZ8 -> 3600 | BB8: 0 | BC8: 0 | BD8: =IF(AK8>0,BA8+BB8+BC8,"0") -> 0 | BE8: =BA8-BD8 -> 3600 | BF8: 0 | BG8: =BE8-BF8 -> 3600 | BH8: =AS8-BD8 -> 0 | BO8: =BI8+BL8 -> 0 | BP8: =BH8-BO8 -> 0 | BQ8: =IF(ROUND(BG8,2)>0,"Advance With Supplier",IF(ROUND(BP8,2)>0,"Payable Balance Supplier","Fully Paid")) -> Advance With Supplier | BS8: =IF(AX8<>"","Closed","Open") -> Open | BT8: =IF(BS8="Open",TODAY()-J8,"Closed") -> 52
A9: Unique Ventures | B9: PRF_Details_Not Availbale | C9: PRF_Details_Not Availbale | D9: Kinshasa | E9: PRF_Details_Not Availbale | F9: Per Pack 100 Amp | G9: =IF(AG9="","GRN Not Received",AW9/AG9) -> 10 | H9: =IF(E9="PRF_Details_Not Availbale","PRF Qty Not Available",IF(G9="GRN Not Received","GRN Not Received",--E9*--G9)) -> PRF Qty Not Available | I9: 043/2024 | J9: 45388 | K9: 4000 | L9: 4.4 | M9: =K9*L9 -> 17600 | N9: 0 | O9: 0 | P9: =M9+O9 -> 17600 | Q9: 23-24/108 | R9: 45381 | S9: Pharmax India Pvt Ltd | T9: FG03867 | U9: =IFERROR(VLOOKUP(T9,'item master'!B:C,2,0),"") -> DIAZEPAM 10MG/2ML INJ B/10AMP | V9: =K9 -> 4000 | W9: 0 | X9: =L9 -> 4.4 | Y9: =V9*X9 -> 17600 | Z9: 0 | AA9: =Y9+Z9 -> 17600 | AB9: 0.3 | AC9: =Y9*AB9 -> 5280 | AD9: =AC9 -> 5280 | AE9: 45463 | AF9: EPHCOP17203Y9ZGA | AG9: 4000 | AH9: =AG9 -> 4000 | AJ9: =V9-AG9 -> 0 | AK9: 24-25/105 | AL9: 45479 | AM9: UNIQUE VENTURES | AN9: 4.4 | AO9: =AG9*AN9 -> 17600 | AS9: =AO9+AP9+AQ9+AR9 -> 17600 | AT9: 242156078 | AU9: 45525 | AV9: Goods Received at Warehouse | AW9: 40000 | AX9: 24KIN/IGRN000261 | AY9: 45573 | AZ9: 0 | BA9: =AD9+AZ9 -> 5280 | BB9: 0 | BC9: 0 | BD9: =IF(AK9>0,BA9+BB9+BC9,"0") -> 5280 | BE9: =BA9-BD9 -> 0 | BF9: 0 | BG9: =BE9-BF9 -> 0 | BH9: =AS9-BD9 -> 12320 | BI9: =BH9 -> 12320 | BJ9: 45500 | BK9: EPHCOP209047ZI1N | BO9: =BI9+BL9 -> 12320 | BP9: =BH9-BO9 -> 0 | BQ9: =IF(ROUND(BG9,2)>0,"Advance With Supplier",IF(ROUND(BP9,2)>0,"Payable Balance Supplier","Fully Paid")) -> Fully Paid | BS9: =IF(AX9<>"","Closed","Open") -> Closed | BT9: =IF(BS9="Open",TODAY()-J9,"Closed") -> Closed
A10: Unique Ventures | B10: PRF_Details_Not Availbale | C10: PRF_Details_Not Availbale | D10: Kinshasa | E10: PRF_Details_Not Availbale | F10: 0 | G10: =IF(AG10="","GRN Not Received",AW10/AG10) -> 1 | H10: =IF(E10="PRF_Details_Not Availbale","PRF Qty Not Available",IF(G10="GRN Not Received","GRN Not Received",--E10*--G10)) -> PRF Qty Not Available | I10: 043/2024 | J10: 45388 | K10: 1000000 | L10: 0.09 | M10: =K10*L10 -> 90000 | N10: 0 | O10: 0 | P10: =M10+O10 -> 90000 | Q10: 23-24/108 | R10: 45381 | S10: Pharmax India Pvt Ltd | T10: FG04047 | U10: =IFERROR(VLOOKUP(T10,'item master'!B:C,2,0),"") -> LINCOMYCINE 600MG INJ.B/1 VIAL | V10: =K10 -> 1000000 | W10: 0 | X10: =L10 -> 0.09 | Y10: =V10*X10 -> 90000 | Z10: 0 | AA10: =Y10+Z10 -> 90000 | AB10: 0.3 | AC10: =Y10*AB10 -> 27000 | AD10: =AC10 -> 27000 | AE10: 45463 | AF10: EPHCOP17203Y9ZGA | AG10: 1011000 | AH10: =AG10 -> 1011000 | AJ10: =V10-AG10 -> -11000 | AK10: 24-25/105 | AL10: 45479 | AM10: UNIQUE VENTURES | AN10: 0.09 | AO10: =AG10*AN10 -> 90990 | AS10: =AO10+AP10+AQ10+AR10 -> 90990 | AT10: 242156078 | AU10: 45525 | AV10: Goods Received at Warehouse | AW10: =926000+85000 -> 1011000 | AX10: 24KIN/IGRN000261 & 24KIN/IGRN000302 | AY10: 08-10-2024 & 12-11-2024 | AZ10: 0 | BA10: =AD10+AZ10 -> 27000 | BB10: 0 | BC10: 297 | BD10: =IF(AK10>0,BA10+BB10+BC10,"0") -> 27297 | BE10: =BA10-BD10 -> -297 | BF10: -297 | BG10: =BE10-BF10 -> 0 | BH10: =AS10-BD10 -> 63693 | BI10: =BH10 -> 63693 | BJ10: 45500 | BK10: EPHCOP209047ZI1N | BO10: =BI10+BL10 -> 63693 | BP10: =BH10-BO10 -> 0 | BQ10: =IF(ROUND(BG10,2)>0,"Advance With Supplier",IF(ROUND(BP10,2)>0,"Payable Balance Supplier","Fully Paid")) -> Fully Paid | BR10: TWO GRN | BS10: =IF(AX10<>"","Closed","Open") -> Closed | BT10: =IF(BS10="Open",TODAY()-J10,"Closed") -> Closed
A11: Unique Ventures | B11: PRF_Details_Not Availbale | C11: PRF_Details_Not Availbale | D11: Kinshasa | E11: PRF_Details_Not Availbale | F11: Per Pack 100 Amp | G11: =IF(AG11="","GRN Not Received",AW11/AG11) -> 10 | H11: =IF(E11="PRF_Details_Not Availbale","PRF Qty Not Available",IF(G11="GRN Not Received","GRN Not Received",--E11*--G11)) -> PRF Qty Not Available | I11: 043/2024 | J11: 45388 | K11: 2000 | L11: 5.3 | M11: =K11*L11 -> 10600 | N11: 0 | O11: 0 | P11: =M11+O11 -> 10600 | Q11: 23-24/108 | R11: 45381 | S11: Pharmax India Pvt Ltd | T11: FG01261 | U11: =IFERROR(VLOOKUP(T11,'item master'!B:C,2,0),"") -> ERGOMETRINE B/10AMP | V11: =K11 -> 2000 | W11: 0 | X11: =L11 -> 5.3 | Y11: =V11*X11 -> 10600 | Z11: 0 | AA11: =Y11+Z11 -> 10600 | AB11: 0.3 | AC11: =Y11*AB11 -> 3180 | AD11: =AC11 -> 3180 | AE11: 45463 | AF11: EPHCOP17203Y9ZGA | AG11: 2000 | AH11: =AG11 -> 2000 | AJ11: =V11-AG11 -> 0 | AK11: 24-25/078 | AL11: 45457 | AM11: UNIQUE VENTURES | AN11: 5.3 | AO11: =AG11*AN11 -> 10600 | AS11: =AO11+AP11+AQ11+AR11 -> 10600 | AT11: AMC2229366 | AU11: 45500 | AV11: Goods Received at Warehouse | AW11: 20000 | AX11: 24KIN/IGRN000234 | AY11: 45544 | AZ11: 0 | BA11: =AD11+AZ11 -> 3180 | BB11: 0 | BC11: 0 | BD11: =IF(AK11>0,BA11+BB11+BC11,"0") -> 3180 | BE11: =BA11-BD11 -> 0 | BF11: 0 | BG11: =BE11-BF11 -> 0 | BH11: =AS11-BD11 -> 7420 | BI11: =BH11 -> 7420 | BJ11: 45500 | BK11: EPHCOP209047ZI1N | BO11: =BI11+BL11 -> 7420 | BP11: =BH11-BO11 -> 0 | BQ11: =IF(ROUND(BG11,2)>0,"Advance With Supplier",IF(ROUND(BP11,2)>0,"Payable Balance Supplier","Fully Paid")) -> Fully Paid | BS11: =IF(AX11<>"","Closed","Open") -> Closed | BT11: =IF(BS11="Open",TODAY()-J11,"Closed") -> Closed
A12: Unique Ventures | B12: PRF_Details_Not Availbale | C12: PRF_Details_Not Availbale | D12: Kinshasa | E12: PRF_Details_Not Availbale | F12: Vial of 20 mL | G12: =IF(AG12="","GRN Not Received",AW12/AG12) -> 1 | H12: =IF(E12="PRF_Details_Not Availbale","PRF Qty Not Available",IF(G12="GRN Not Received","GRN Not Received",--E12*--G12)) -> PRF Qty Not Available | I12: 043/2024 | J12: 45388 | K12: 100000 | L12: 0.11 | M12: =K12*L12 -> 11000 | N12: 0 | O12: 0 | P12: =M12+O12 -> 11000 | Q12: 23-24/108 | R12: 45381 | S12: Pharmax India Pvt Ltd | T12: FG04097 | U12: =IFERROR(VLOOKUP(T12,'item master'!B:C,2,0),"") -> UNICAINE 2% (LIDOCAIN) INJ. FL/20ML | V12: =K12 -> 100000 | W12: 0 | X12: =L12 -> 0.11 | Y12: =V12*X12 -> 11000 | Z12: 0 | AA12: =Y12+Z12 -> 11000 | AB12: 0.3 | AC12: =Y12*AB12 -> 3300 | AD12: =AC12 -> 3300 | AE12: 45463 | AF12: EPHCOP17203Y9ZGA | AG12: 100000 | AH12: =AG12 -> 100000 | AJ12: =V12-AG12 -> 0 | AK12: 24-25/078 | AL12: 45457 | AM12: UNIQUE VENTURES | AN12: 0.11 | AO12: =AG12*AN12 -> 11000 | AS12: =AO12+AP12+AQ12+AR12 -> 11000 | AT12: AMC2229366 | AU12: 45500 | AV12: Goods Received at Warehouse | AW12: 100000 | AX12: 24KIN/IGRN000234 | AY12: 45544 | AZ12: 0 | BA12: =AD12+AZ12 -> 3300 | BB12: 0 | BC12: 0 | BD12: =IF(AK12>0,BA12+BB12+BC12,"0") -> 3300 | BE12: =BA12-BD12 -> 0 | BF12: 0 | BG12: =BE12-BF12 -> 0 | BH12: =AS12-BD12 -> 7700 | BI12: =BH12 -> 7700 | BJ12: 45500 | BK12: EPHCOP209047ZI1N | BO12: =BI12+BL12 -> 7700 | BP12: =BH12-BO12 -> 0 | BQ12: =IF(ROUND(BG12,2)>0,"Advance With Supplier",IF(ROUND(BP12,2)>0,"Payable Balance Supplier","Fully Paid")) -> Fully Paid | BS12: =IF(AX12<>"","Closed","Open") -> Closed | BT12: =IF(BS12="Open",TODAY()-J12,"Closed") -> Closed
A13: Unique Ventures | B13: PRF_Details_Not Availbale | C13: PRF_Details_Not Availbale | D13: Kinshasa | E13: PRF_Details_Not Availbale | F13: Vial of 20 mL | G13: =IF(AG13="","GRN Not Received",AW13/AG13) -> 1 | H13: =IF(E13="PRF_Details_Not Availbale","PRF Qty Not Available",IF(G13="GRN Not Received","GRN Not Received",--E13*--G13)) -> PRF Qty Not Available | I13: 043/2024 | J13: 45388 | K13: 0 | L13: 0 | M13: =K13*L13 -> 0 | N13: 0 | O13: 0 | P13: =M13+O13 -> 0 | Q13: 23-24/108 | R13: 45381 | S13: Pharmax India Pvt Ltd | T13: FG04097 | U13: =IFERROR(VLOOKUP(T13,'item master'!B:C,2,0),"") -> UNICAINE 2% (LIDOCAIN) INJ. FL/20ML | V13: =K13 -> 0 | W13: 0 | X13: =L13 -> 0 | Y13: =V13*X13 -> 0 | Z13: 0 | AA13: =Y13+Z13 -> 0 | AD13: 0 | AG13: 1600 | AH13: =AG13 -> 1600 | AJ13: =V13-AG13 -> -1600 | AK13: 24-25/387 | AL13: 45668 | AM13: UNIQUE VENTURES | AN13: 0.11 | AO13: =AG13*AN13 -> 176 | AS13: =AO13+AP13+AQ13+AR13 -> 176 | AT13: AMC2353209 | AU13: 45700 | AV13: Goods Received at Warehouse | AW13: 1600 | AX13: 25KIN1/IGRN000048 | AY13: 45747 | AZ13: 0 | BA13: =AD13+AZ13 -> 0 | BB13: 0 | BC13: 0 | BD13: =IF(AK13>0,BA13+BB13+BC13,"0") -> 0 | BE13: =BA13-BD13 -> 0 | BF13: 0 | BG13: =BE13-BF13 -> 0 | BH13: =AS13-BD13 -> 176 | BI13: =BH13 -> 176 | BJ13: 45765 | BK13: SWIFT COPY NOT AVAILABLE | BO13: =BI13+BL13 -> 176 | BP13: =BH13-BO13 -> 0 | BQ13: =IF(ROUND(BG13,2)>0,"Advance With Supplier",IF(ROUND(BP13,2)>0,"Payable Balance Supplier","Fully Paid")) -> Fully Paid | BS13: =IF(AX13<>"","Closed","Open") -> Closed | BT13: =IF(BS13="Open",TODAY()-J13,"Closed") -> Closed
A14: Unique Ventures | B14: PRF_Details_Not Availbale | C14: PRF_Details_Not Availbale | D14: Kinshasa | E14: PRF_Details_Not Availbale | F14: Per Vial | G14: =IF(AG14="","GRN Not Received",AW14/AG14) -> 1 | H14: =IF(E14="PRF_Details_Not Availbale","PRF Qty Not Available",IF(G14="GRN Not Received","GRN Not Received",--E14*--G14)) -> PRF Qty Not Available | I14: 043/2024 | J14: 45388 | K14: 20000 | L14: 0.5 | M14: =K14*L14 -> 10000 | N14: 0 | O14: 0 | P14: =M14+O14 -> 10000 | Q14: 23-24/108 | R14: 45381 | S14: Pharmax India Pvt Ltd | T14: FG06812 | U14: =IFERROR(VLOOKUP(T14,'item master'!B:C,2,0),"") -> UNIKORT-80 (TRIAMCINOLONE) B/1 VIAL +SER | V14: =K14 -> 20000 | W14: 0 | X14: =L14 -> 0.5 | Y14: =V14*X14 -> 10000 | Z14: 0 | AA14: =Y14+Z14 -> 10000 | AB14: 0.3 | AC14: =Y14*AB14 -> 3000 | AD14: =AC14 -> 3000 | AE14: 45463 | AF14: EPHCOP17203Y9ZGA | AG14: 19800 | AH14: =AG14 -> 19800 | AJ14: =V14-AG14 -> 200 | AK14: 24-25/105 | AL14: 45457 | AM14: UNIQUE VENTURES | AN14: 0.5 | AO14: =AG14*AN14 -> 9900 | AS14: =AO14+AP14+AQ14+AR14 -> 9900 | AT14: 242156078 | AU14: 45525 | AV14: Goods Received at Warehouse | AW14: 19800 | AX14: 24KIN/IGRN000261 | AY14: 45573 | AZ14: 0 | BA14: =AD14+AZ14 -> 3000 | BB14: 0 | BC14: -30 | BD14: =IF(AK14>0,BA14+BB14+BC14,"0") -> 2970 | BE14: =BA14-BD14 -> 30 | BF14: 30 | BG14: =BE14-BF14 -> 0 | BH14: =AS14-BD14 -> 6930 | BI14: =BH14 -> 6930 | BJ14: 45500 | BK14: EPHCOP209047ZI1N | BO14: =BI14+BL14 -> 6930 | BP14: =BH14-BO14 -> 0 | BQ14: =IF(ROUND(BG14,2)>0,"Advance With Supplier",IF(ROUND(BP14,2)>0,"Payable Balance Supplier","Fully Paid")) -> Fully Paid | BS14: =IF(AX14<>"","Closed","Open") -> Closed | BT14: =IF(BS14="Open",TODAY()-J14,"Closed") -> Closed
A15: Unique Ventures | B15: PRF_Details_Not Availbale | C15: PRF_Details_Not Availbale | D15: Kinshasa | E15: PRF_Details_Not Availbale | F15: 0 | G15: =IF(AG15="","GRN Not Received",AW15/AG15) -> 1 | H15: =IF(E15="PRF_Details_Not Availbale","PRF Qty Not Available",IF(G15="GRN Not Received","GRN Not Received",--E15*--G15)) -> PRF Qty Not Available | I15: 043/2024 | J15: 45388 | K15: 10000 | L15: 1.1 | M15: =K15*L15 -> 11000 | N15: 0 | O15: 0 | P15: =M15+O15 -> 11000 | Q15: 23-24/108 | R15: 45381 | S15: Pharmax India Pvt Ltd | T15: FG06678 | U15: =IFERROR(VLOOKUP(T15,'item master'!B:C,2,0),"") -> HEPAQUE (HEPARIN) 25000UI/5ML INJ. B/1 VIAL | V15: =K15 -> 10000 | W15: 0 | X15: =L15 -> 1.1 | Y15: =V15*X15 -> 11000 | Z15: 0 | AA15: =Y15+Z15 -> 11000 | AB15: 0.3 | AC15: =Y15*AB15 -> 3300 | AD15: =AC15 -> 3300 | AE15: 45463 | AF15: EPHCOP17203Y9ZGA | AG15: 9600 | AH15: =AG15 -> 9600 | AJ15: =V15-AG15 -> 400 | AK15: 24-25/322 | AL15: 45625 | AM15: UNIQUE VENTURES | AN15: =X15 -> 1.1 | AO15: =AG15*AN15 -> 10560 | AS15: =AO15+AP15+AQ15+AR15 -> 10560 | AT15: AMC2336146 | AU15: 45667 | AV15: Goods Received at Warehouse | AW15: 9600 | AX15: 25KIN/IGRN000021 | AY15: 45721 | AZ15: -297 | BA15: =AD15+AZ15 -> 3003 | BB15: 450 | BC15: 80 | BD15: =IF(AK15>0,BA15+BB15+BC15,"0") -> 3533 | BE15: =BA15-BD15 -> -530 | BF15: -530 | BG15: =BE15-BF15 -> 0 | BH15: =AS15-BD15 -> 7027 | BI15: =BH15 -> 7027 | BJ15: 45765 | BK15: SWIFT COPY NOT AVAILABLE | BO15: =BI15+BL15 -> 7027 | BP15: =BH15-BO15 -> 0 | BQ15: =IF(ROUND(BG15,2)>0,"Advance With Supplier",IF(ROUND(BP15,2)>0,"Payable Balance Supplier","Fully Paid")) -> Fully Paid | BS15: =IF(AX15<>"","Closed","Open") -> Closed | BT15: =IF(BS15="Open",TODAY()-J15,"Closed") -> Closed
A16: Unique Ventures | B16: PRF_Details_Not Availbale | C16: PRF_Details_Not Availbale | D16: Kinshasa | E16: PRF_Details_Not Availbale | F16: Per Vial | G16: =IF(AG16="","GRN Not Received",AW16/AG16) -> 1 | H16: =IF(E16="PRF_Details_Not Availbale","PRF Qty Not Available",IF(G16="GRN Not Received","GRN Not Received",--E16*--G16)) -> PRF Qty Not Available | I16: 043/2024 | J16: 45388 | K16: 30000 | L16: 0.95 | M16: =K16*L16 -> 28500 | N16: 0 | O16: 0 | P16: =M16+O16 -> 28500 | Q16: 23-24/108 | R16: 45381 | S16: Pharmax India Pvt Ltd | T16: FG06804 | U16: =IFERROR(VLOOKUP(T16,'item master'!B:C,2,0),"") -> TROBINIQUE-2G(SPECTINOMYCIN) B/1VIAL+3.2MLE.D | V16: =K16 -> 30000 | W16: 0 | X16: =L16 -> 0.95 | Y16: =V16*X16 -> 28500 | Z16: 0 | AA16: =Y16+Z16 -> 28500 | AB16: 0.3 | AC16: =Y16*AB16 -> 8550 | AD16: =AC16 -> 8550 | AE16: 45463 | AF16: EPHCOP17203Y9ZGA | AG16: 30000 | AH16: =AG16 -> 30000 | AJ16: =V16-AG16 -> 0 | AK16: 24-25/105 | AL16: 45479 | AM16: UNIQUE VENTURES | AN16: 0.95 | AO16: =AG16*AN16 -> 28500 | AS16: =AO16+AP16+AQ16+AR16 -> 28500 | AT16: 242156078 | AU16: 45525 | AV16: Goods Received at Warehouse | AW16: 30000 | AX16: 24KIN/IGRN000261 | AY16: 45573 | AZ16: 0 | BA16: =AD16+AZ16 -> 8550 | BB16: 0 | BC16: 0 | BD16: =IF(AK16>0,BA16+BB16+BC16,"0") -> 8550 | BE16: =BA16-BD16 -> 0 | BF16: 0 | BG16: =BE16-BF16 -> 0 | BH16: =AS16-BD16 -> 19950 | BI16: =BH16 -> 19950 | BJ16: 45500 | BK16: EPHCOP209047ZI1N | BO16: =BI16+BL16 -> 19950 | BP16: =BH16-BO16 -> 0 | BQ16: =IF(ROUND(BG16,2)>0,"Advance With Supplier",IF(ROUND(BP16,2)>0,"Payable Balance Supplier","Fully Paid")) -> Fully Paid | BS16: =IF(AX16<>"","Closed","Open") -> Closed | BT16: =IF(BS16="Open",TODAY()-J16,"Closed") -> Closed
A17: Unique Ventures | B17: PRF_Details_Not Availbale | C17: PRF_Details_Not Availbale | D17: Kinshasa | E17: PRF_Details_Not Availbale | F17: 0 | G17: =IF(AG17="","GRN Not Received",AW17/AG17) -> 1 | H17: =IF(E17="PRF_Details_Not Availbale","PRF Qty Not Available",IF(G17="GRN Not Received","GRN Not Received",--E17*--G17)) -> PRF Qty Not Available | I17: 043/2024 | J17: 45388 | K17: 2000 | L17: 2.2 | M17: =K17*L17 -> 4400 | N17: 0 | O17: 0 | P17: =M17+O17 -> 4400 | Q17: 23-24/108 | R17: 45381 | S17: Pharmax India Pvt Ltd | T17: FG07424 | U17: =IFERROR(VLOOKUP(T17,'item master'!B:C,2,0),"") -> PANCUR 4MG/2ML (PANCURONIUM) INJ. B/10 AMP | V17: =K17 -> 2000 | W17: 0 | X17: =L17 -> 2.2 | Y17: =V17*X17 -> 4400 | Z17: 0 | AA17: =Y17+Z17 -> 4400 | AB17: 0.3 | AC17: =Y17*AB17 -> 1320 | AD17: =AC17 -> 1320 | AE17: 45463 | AF17: EPHCOP17203Y9ZGA | AG17: 1970 | AH17: =AG17 -> 1970 | AJ17: =V17-AG17 -> 30 | AK17: 24-25/192 | AL17: 45537 | AM17: UNIQUE VENTURES | AN17: 2.2 | AO17: =AG17*AN17 -> 4334 | AS17: =AO17+AP17+AQ17+AR17 -> 4334 | AT17: 244450371 | AV17: Goods Received at Warehouse | AW17: 1970 | AX17: 24KIN/IGRN000302 | AY17: 45608 | AZ17: 0 | BA17: =AD17+AZ17 -> 1320 | BB17: 0 | BC17: -19.8 | BD17: =IF(AK17>0,BA17+BB17+BC17,"0") -> 1300.2 | BE17: =BA17-BD17 -> 19.8 | BF17: 19.8 | BG17: =BE17-BF17 -> -4.6185278e-14 | BH17: =AS17-BD17 -> 3033.8 | BI17: =BH17 -> 3033.8 | BJ17: 45586 | BK17: EPHCOP29504UC6MI | BO17: =BI17+BL17 -> 3033.8 | BP17: =BH17-BO17 -> 0 | BQ17: =IF(ROUND(BG17,2)>0,"Advance With Supplier",IF(ROUND(BP17,2)>0,"Payable Balance Supplier","Fully Paid")) -> Fully Paid | BS17: =IF(AX17<>"","Closed","Open") -> Closed | BT17: =IF(BS17="Open",TODAY()-J17,"Closed") -> Closed
A18: Unique Ventures | B18: PRF_Details_Not Availbale | C18: PRF_Details_Not Availbale | D18: Kinshasa | E18: PRF_Details_Not Availbale | F18: 0 | G18: =IF(AG18="","GRN Not Received",AW18/AG18) -> 1 | H18: =IF(E18="PRF_Details_Not Availbale","PRF Qty Not Available",IF(G18="GRN Not Received","GRN Not Received",--E18*--G18)) -> PRF Qty Not Available | I18: 043/2024 | J18: 45388 | K18: 100000 | L18: 0.0675 | M18: =K18*L18 -> 6750 | N18: 0 | O18: 0 | P18: =M18+O18 -> 6750 | Q18: 23-24/108 | R18: 45381 | S18: Pharmax India Pvt Ltd | T18: FG04611 | U18: =IFERROR(VLOOKUP(T18,'item master'!B:C,2,0),"") -> CHLORAMPHENICOL 0.5% COLLYRE 10ML | V18: =K18 -> 100000 | W18: 0 | X18: =L18 -> 0.0675 | Y18: =V18*X18 -> 6750 | Z18: 0 | AA18: =Y18+Z18 -> 6750 | AB18: 0.3 | AC18: =Y18*AB18 -> 2025 | AD18: =AC18 -> 2025 | AE18: 45463 | AF18: EPHCOP17203Y9ZGA | AG18: 99320 | AH18: =AG18 -> 99320 | AJ18: =V18-AG18 -> 680 | AK18: 24-25/105 | AL18: 45479 | AM18: UNIQUE VENTURES | AN18: 0.0675 | AO18: =AG18*AN18 -> 6704.1 | AS18: =AO18+AP18+AQ18+AR18 -> 6704.1 | AT18: 242156078 | AU18: 45525 | AV18: Goods Received at Warehouse | AW18: 99320 | AX18: 24KIN/IGRN000261 | AY18: 45573 | AZ18: 0 | BA18: =AD18+AZ18 -> 2025 | BB18: 0 | BC18: -13.77 | BD18: =IF(AK18>0,BA18+BB18+BC18,"0") -> 2011.23 | BE18: =BA18-BD18 -> 13.77 | BF18: 13.77 | BG18: =BE18-BF18 -> -1.7763568e-14 | BH18: =AS18-BD18 -> 4692.87 | BI18: =BH18 -> 4692.87 | BJ18: 45500 | BK18: EPHCOP209047ZI1N | BO18: =BI18+BL18 -> 4692.87 | BP18: =BH18-BO18 -> 0 | BQ18: =IF(ROUND(BG18,2)>0,"Advance With Supplier",IF(ROUND(BP18,2)>0,"Payable Balance Supplier","Fully Paid")) -> Fully Paid | BS18: =IF(AX18<>"","Closed","Open") -> Closed | BT18: =IF(BS18="Open",TODAY()-J18,"Closed") -> Closed
A19: Unique Ventures | B19: PRF_Details_Not Availbale | C19: PRF_Details_Not Availbale | D19: Kinshasa | E19: PRF_Details_Not Availbale | F19: 0 | G19: =IF(AG19="","GRN Not Received",AW19/AG19) -> 1 | H19: =IF(E19="PRF_Details_Not Availbale","PRF Qty Not Available",IF(G19="GRN Not Received","GRN Not Received",--E19*--G19)) -> PRF Qty Not Available | I19: 043/2024 | J19: 45388 | K19: 5000 | L19: 0.52 | M19: =K19*L19 -> 2600 | N19: 0 | O19: 0 | P19: =M19+O19 -> 2600 | Q19: 23-24/108 | R19: 45381 | S19: Pharmax India Pvt Ltd | T19: FG07409 | U19: =IFERROR(VLOOKUP(T19,'item master'!B:C,2,0),"") -> HEMOSTAT 250MG/2ML (ETAMSYLATE) INJ.B/4 AMP. | V19: =K19 -> 5000 | W19: 0 | X19: =L19 -> 0.52 | Y19: =V19*X19 -> 2600 | Z19: 0 | AA19: =Y19+Z19 -> 2600 | AB19: 0.3 | AC19: =Y19*AB19 -> 780 | AD19: =AC19 -> 780 | AE19: 45463 | AF19: EPHCOP17203Y9ZGA | AG19: 5000 | AH19: =AG19 -> 5000 | AJ19: =V19-AG19 -> 0 | AK19: 24-25/436 | AL19: 45695 | AM19: UNIQUE VENTURES | AN19: 0.52 | AO19: =AG19*AN19 -> 2600 | AS19: =AO19+AP19+AQ19+AR19 -> 2600 | AT19: 2515134444 | AV19: Goods Received at Warehouse | AW19: 5000 | AX19: 25KIN1/IGRN000088 | AZ19: 19.8 | BA19: =AD19+AZ19 -> 799.8 | BB19: 0 | BC19: 0 | BD19: =IF(AK19>0,BA19+BB19+BC19,"0") -> 799.8 | BE19: =BA19-BD19 -> 0 | BF19: 0 | BG19: =BE19-BF19 -> 0 | BH19: =AS19-BD19 -> 1800.2 | BI19: =BH19 -> 1800.2 | BJ19: 45765 | BK19: SWIFT COPY NOT AVAILABLE | BO19: =BI19+BL19 -> 1800.2 | BP19: =BH19-BO19 -> 0 | BQ19: =IF(ROUND(BG19,2)>0,"Advance With Supplier",IF(ROUND(BP19,2)>0,"Payable Balance Supplier","Fully Paid")) -> Fully Paid | BS19: =IF(AX19<>"","Closed","Open") -> Closed | BT19: =IF(BS19="Open",TODAY()-J19,"Closed") -> Closed
A20: Unique Ventures | B20: PRF_Details_Not Availbale | C20: PRF_Details_Not Availbale | D20: Kinshasa | E20: PRF_Details_Not Availbale | F20: 0 | G20: =IF(AG20="","GRN Not Received",AW20/AG20) -> 1 | H20: =IF(E20="PRF_Details_Not Availbale","PRF Qty Not Available",IF(G20="GRN Not Received","GRN Not Received",--E20*--G20)) -> PRF Qty Not Available | I20: 043/2024 | J20: 45388 | K20: 20000 | L20: 0.22 | M20: =K20*L20 -> 4400 | N20: 0 | O20: 0 | P20: =M20+O20 -> 4400 | Q20: 23-24/108 | R20: 45381 | S20: Pharmax India Pvt Ltd | T20: FG07415 | U20: =IFERROR(VLOOKUP(T20,'item master'!B:C,2,0),"") -> VOMITRON 0.075 MG/1.5ML (PALONOSÉTRON) INJ. B/1 VIAL | V20: =K20 -> 20000 | W20: 0 | X20: =L20 -> 0.22 | Y20: =V20*X20 -> 4400 | Z20: 0 | AA20: =Y20+Z20 -> 4400 | AB20: 0.3 | AC20: =Y20*AB20 -> 1320 | AD20: =AC20 -> 1320 | AE20: 45463 | AF20: EPHCOP17203Y9ZGA | AG20: 19750 | AH20: =AG20 -> 19750 | AJ20: =V20-AG20 -> 250 | AK20: 24-25/192 | AL20: 45537 | AM20: UNIQUE VENTURES | AN20: 0.22 | AO20: =AG20*AN20 -> 4345 | AS20: =AO20+AP20+AQ20+AR20 -> 4345 | AT20: 244450371 | AV20: Goods Received at Warehouse | AW20: 19750 | AX20: 24KIN/IGRN000302 | AY20: 45608 | AZ20: 0 | BA20: =AD20+AZ20 -> 1320 | BB20: 0 | BC20: -16.5 | BD20: =IF(AK20>0,BA20+BB20+BC20,"0") -> 1303.5 | BE20: =BA20-BD20 -> 16.5 | BF20: 16.5 | BG20: =BE20-BF20 -> 0 | BH20: =AS20-BD20 -> 3041.5 | BI20: =BH20 -> 3041.5 | BJ20: 45586 | BK20: EPHCOP29504UC6MI | BO20: =BI20+BL20 -> 3041.5 | BP20: =BH20-BO20 -> 0 | BQ20: =IF(ROUND(BG20,2)>0,"Advance With Supplier",IF(ROUND(BP20,2)>0,"Payable Balance Supplier","Fully Paid")) -> Fully Paid | BS20: =IF(AX20<>"","Closed","Open") -> Closed | BT20: =IF(BS20="Open",TODAY()-J20,"Closed") -> Closed
A21: Unique Ventures | B21: PRF_Details_Not Availbale | C21: PRF_Details_Not Availbale | D21: Kinshasa | E21: PRF_Details_Not Availbale | F21: 0 | G21: =IF(AG21="","GRN Not Received",AW21/AG21) -> 1 | H21: =IF(E21="PRF_Details_Not Availbale","PRF Qty Not Available",IF(G21="GRN Not Received","GRN Not Received",--E21*--G21)) -> PRF Qty Not Available | I21: 043/2024 | J21: 45388 | K21: 15000 | L21: 0.16 | M21: =K21*L21 -> 2400 | N21: 0 | O21: 0 | P21: =M21+O21 -> 2400 | Q21: 23-24/108 | R21: 45381 | S21: Pharmax India Pvt Ltd | T21: FG07413 | U21: =IFERROR(VLOOKUP(T21,'item master'!B:C,2,0),"") -> H-CID 20MG/2ML (FAMOTIDINE ) INJ. B/1 VIAL | V21: =K21 -> 15000 | W21: 0 | X21: =L21 -> 0.16 | Y21: =V21*X21 -> 2400 | Z21: 0 | AA21: =Y21+Z21 -> 2400 | AB21: 0.3 | AC21: =Y21*AB21 -> 720 | AD21: =AC21 -> 720 | AE21: 45463 | AF21: EPHCOP17203Y9ZGA | AG21: 15160 | AH21: =AG21 -> 15160 | AJ21: =V21-AG21 -> -160 | AK21: 24-25/322 | AL21: 45625 | AM21: UNIQUE VENTURES | AN21: =X21 -> 0.16 | AO21: =AG21*AN21 -> 2425.6 | AS21: =AO21+AP21+AQ21+AR21 -> 2425.6 | AT21: AMC2336146 | AU21: 45667 | AV21: Goods Received at Warehouse | AW21: 15160 | AX21: 25KIN/IGRN000021 | AY21: 45721 | AZ21: 16.5 | BA21: =AD21+AZ21 -> 736.5 | BB21: 828 | BC21: 0 | BD21: =IF(AK21>0,BA21+BB21+BC21,"0") -> 1564.5 | BE21: =BA21-BD21 -> -828 | BF21: -828 | BG21: =BE21-BF21 -> 0 | BH21: =AS21-BD21 -> 861.1 | BI21: =BH21 -> 861.1 | BJ21: 45765 | BK21: SWIFT COPY NOT AVAILABLE | BO21: =BI21+BL21 -> 861.1 | BP21: =BH21-BO21 -> 0 | BQ21: =IF(ROUND(BG21,2)>0,"Advance With Supplier",IF(ROUND(BP21,2)>0,"Payable Balance Supplier","Fully Paid")) -> Fully Paid | BS21: =IF(AX21<>"","Closed","Open") -> Closed | BT21: =IF(BS21="Open",TODAY()-J21,"Closed") -> Closed
A22: Unique Ventures | B22: PRF_Details_Not Availbale | C22: PRF_Details_Not Availbale | D22: Kinshasa | E22: PRF_Details_Not Availbale | F22: 0 | G22: =IF(AG22="","GRN Not Received",AW22/AG22) -> 1 | H22: =IF(E22="PRF_Details_Not Availbale","PRF Qty Not Available",IF(G22="GRN Not Received","GRN Not Received",--E22*--G22)) -> PRF Qty Not Available | I22: 043/2024 | J22: 45388 | K22: 10000 | L22: 0.25 | M22: =K22*L22 -> 2500 | N22: 0 | O22: 0 | P22: =M22+O22 -> 2500 | Q22: 23-24/108 | R22: 45381 | S22: Pharmax India Pvt Ltd | T22: FG07418 | U22: =IFERROR(VLOOKUP(T22,'item master'!B:C,2,0),"") -> KETOFEN 100MG/2ML ( KÉTOPROFÈNE) INJ. B/5AMP | V22: =K22 -> 10000 | W22: 0 | X22: =L22 -> 0.25 | Y22: =V22*X22 -> 2500 | Z22: 0 | AA22: =Y22+Z22 -> 2500 | AB22: 0.3 | AC22: =Y22*AB22 -> 750 | AD22: =AC22 -> 750 | AE22: 45463 | AF22: EPHCOP17203Y9ZGA | AG22: 9000 | AH22: =AG22 -> 9000 | AJ22: =V22-AG22 -> 1000 | AK22: 24-25/192 | AL22: 45537 | AM22: UNIQUE VENTURES | AN22: 0.25 | AO22: =AG22*AN22 -> 2250 | AS22: =AO22+AP22+AQ22+AR22 -> 2250 | AT22: 244450371 | AV22: Goods Received at Warehouse | AW22: 9000 | AX22: 24KIN/IGRN000302 | AY22: 45608 | AZ22: 0 | BA22: =AD22+AZ22 -> 750 | BB22: 0 | BC22: -75 | BD22: =IF(AK22>0,BA22+BB22+BC22,"0") -> 675 | BE22: =BA22-BD22 -> 75 | BF22: 75 | BG22: =BE22-BF22 -> 0 | BH22: =AS22-BD22 -> 1575 | BI22: =BH22 -> 1575 | BJ22: 45586 | BK22: EPHCOP29504UC6MI | BO22: =BI22+BL22 -> 1575 | BP22: =BH22-BO22 -> 0 | BQ22: =IF(ROUND(BG22,2)>0,"Advance With Supplier",IF(ROUND(BP22,2)>0,"Payable Balance Supplier","Fully Paid")) -> Fully Paid | BS22: =IF(AX22<>"","Closed","Open") -> Closed | BT22: =IF(BS22="Open",TODAY()-J22,"Closed") -> Closed
A23: Unique Ventures | B23: PRF_Details_Not Availbale | C23: PRF_Details_Not Availbale | D23: Kinshasa | E23: PRF_Details_Not Availbale | F23: 0 | G23: =IF(AG23="","GRN Not Received",AW23/AG23) -> 1 | H23: =IF(E23="PRF_Details_Not Availbale","PRF Qty Not Available",IF(G23="GRN Not Received","GRN Not Received",--E23*--G23)) -> PRF Qty Not Available | I23: 043/2024 | J23: 45388 | K23: 3000 | L23: 0.9 | M23: =K23*L23 -> 2700 | N23: 0 | O23: 0 | P23: =M23+O23 -> 2700 | Q23: 23-24/108 | R23: 45381 | S23: Pharmax India Pvt Ltd | T23: FG07423 | U23: =IFERROR(VLOOKUP(T23,'item master'!B:C,2,0),"") -> NIMOTRIX 10MG (NIMODIPINE) IV B/50ML VIAL | V23: =K23 -> 3000 | W23: 0 | X23: =L23 -> 0.9 | Y23: =V23*X23 -> 2700 | Z23: 0 | AA23: =Y23+Z23 -> 2700 | AB23: 0.3 | AC23: =Y23*AB23 -> 810 | AD23: =AC23 -> 810 | AE23: 45463 | AF23: EPHCOP17203Y9ZGA | AG23: 3050 | AH23: =AG23 -> 3050 | AJ23: =V23-AG23 -> -50 | AK23: 24-25/192 | AL23: 45537 | AM23: UNIQUE VENTURES | AN23: 0.9 | AO23: =AG23*AN23 -> 2745 | AS23: =AO23+AP23+AQ23+AR23 -> 2745 | AT23: 244450371 | AV23: Goods Received at Warehouse | AW23: 3050 | AX23: 24KIN/IGRN000302 | AY23: 45608 | AZ23: 0 | BA23: =AD23+AZ23 -> 810 | BB23: 0 | BC23: 13.5 | BD23: =IF(AK23>0,BA23+BB23+BC23,"0") -> 823.5 | BE23: =BA23-BD23 -> -13.5 | BF23: -13.5 | BG23: =BE23-BF23 -> 0 | BH23: =AS23-BD23 -> 1921.5 | BI23: =BH23 -> 1921.5 | BJ23: 45586 | BK23: EPHCOP29504UC6MI | BO23: =BI23+BL23 -> 1921.5 | BP23: =BH23-BO23 -> 0 | BQ23: =IF(ROUND(BG23,2)>0,"Advance With Supplier",IF(ROUND(BP23,2)>0,"Payable Balance Supplier","Fully Paid")) -> Fully Paid | BS23: =IF(AX23<>"","Closed","Open") -> Closed | BT23: =IF(BS23="Open",TODAY()-J23,"Closed") -> Closed
A24: Unique Ventures | B24: PRF_Details_Not Availbale | C24: PRF_Details_Not Availbale | D24: Kinshasa | E24: PRF_Details_Not Availbale | F24: 0 | G24: =IF(AG24="","GRN Not Received",AW24/AG24) -> 1 | H24: =IF(E24="PRF_Details_Not Availbale","PRF Qty Not Available",IF(G24="GRN Not Received","GRN Not Received",--E24*--G24)) -> PRF Qty Not Available | I24: 043/2024 | J24: 45388 | K24: 3000 | L24: 0.5 | M24: =K24*L24 -> 1500 | N24: 0 | O24: 0 | P24: =M24+O24 -> 1500 | Q24: 23-24/108 | R24: 45381 | S24: Pharmax India Pvt Ltd | T24: FG07425 | U24: =IFERROR(VLOOKUP(T24,'item master'!B:C,2,0),"") -> PHAMINE 22,75MG/ML (MALÉATE DE PHÉNIRAMINE) 2ML INJ. B/10 AMP | V24: =K24 -> 3000 | W24: 0 | X24: =L24 -> 0.5 | Y24: =V24*X24 -> 1500 | Z24: 0 | AA24: =Y24+Z24 -> 1500 | AB24: 0.3 | AC24: =Y24*AB24 -> 450 | AD24: =AC24 -> 450 | AE24: 45463 | AF24: EPHCOP17203Y9ZGA | AG24: 3100 | AH24: =AG24 -> 3100 | AJ24: =V24-AG24 -> -100 | AK24: 25-26/079 | AL24: 45804 | AM24: UNIQUE VENTURES | AN24: 0.5 | AO24: =AG24*AN24 -> 1550 | AS24: =AO24+AP24+AQ24+AR24 -> 1550 | AT24: 255404858 | AV24: Goods Received at Warehouse | AW24: 3100 | AX24: 25KIN1/IGRN000203 | AY24: 45891 | AZ24: 0 | BA24: =AD24+AZ24 -> 450 | BB24: 0 | BC24: 0 | BD24: =IF(AK24>0,BA24+BB24+BC24,"0") -> 450 | BE24: =BA24-BD24 -> 0 | BF24: 0 | BG24: =BE24-BF24 -> 0 | BH24: =AS24-BD24 -> 1100 | BI24: =BH24 -> 1100 | BJ24: 45895 | BK24: EPHCOP23807H9WMK | BO24: =BI24+BL24 -> 1100 | BP24: =BH24-BO24 -> 0 | BQ24: =IF(ROUND(BG24,2)>0,"Advance With Supplier",IF(ROUND(BP24,2)>0,"Payable Balance Supplier","Fully Paid")) -> Fully Paid | BS24: =IF(AX24<>"","Closed","Open") -> Closed | BT24: =IF(BS24="Open",TODAY()-J24,"Closed") -> Closed
A25: Unique Ventures | B25: PRF_Details_Not Availbale | C25: PRF_Details_Not Availbale | D25: Kinshasa | E25: PRF_Details_Not Availbale | F25: 0 | G25: =IF(AG25="","GRN Not Received",AW25/AG25) -> 1 | H25: =IF(E25="PRF_Details_Not Availbale","PRF Qty Not Available",IF(G25="GRN Not Received","GRN Not Received",--E25*--G25)) -> PRF Qty Not Available | I25: 043/2024 | J25: 45388 | K25: 3000 | L25: 0.92 | M25: =K25*L25 -> 2760 | N25: 0 | O25: 0 | P25: =M25+O25 -> 2760 | Q25: 23-24/108 | R25: 45381 | S25: Pharmax India Pvt Ltd | T25: FG07411 | U25: =IFERROR(VLOOKUP(T25,'item master'!B:C,2,0),"") -> UNITRIM 480MG/5ML (CO-TRIMOXAZOLE) INJ. B/5 AMP. | V25: =K25 -> 3000 | W25: 0 | X25: =L25 -> 0.92 | Y25: =V25*X25 -> 2760 | Z25: 0 | AA25: =Y25+Z25 -> 2760 | AB25: 0.3 | AC25: =Y25*AB25 -> 828 | AD25: =AC25 -> 828 | AE25: 45463 | AF25: EPHCOP17203Y9ZGA | AG25: 2960 | AH25: =AG25 -> 2960 | AJ25: =V25-AG25 -> 40 | AK25: 25-26/437 | AL25: 46024 | AM25: UNIQUE VENTURES | AN25: 0.92 | AO25: =AG25*AN25 -> 2723.2 | AS25: =AO25+AP25+AQ25+AR25 -> 2723.2 | AT25: 266199219 | AU25: 46091 | AV25: Goods Received at Warehouse | AW25: 2960 | AX25: 26KIN1/IGRN000130 | AZ25: -828 | BA25: =AD25+AZ25 -> 0 | BB25: 0 | BC25: 0 | BD25: =IF(AK25>0,BA25+BB25+BC25,"0") -> 0 | BE25: =BA25-BD25 -> 0 | BF25: 0 | BG25: =BE25-BF25 -> 0 | BH25: =AS25-BD25 -> 2723.2 | BI25: 2723.2 | BJ25: 46234 | BO25: =BI25+BL25 -> 2723.2 | BP25: =BH25-BO25 -> 0 | BQ25: =IF(ROUND(BG25,2)>0,"Advance With Supplier",IF(ROUND(BP25,2)>0,"Payable Balance Supplier","Fully Paid")) -> Fully Paid | BS25: =IF(AX25<>"","Closed","Open") -> Closed | BT25: =IF(BS25="Open",TODAY()-J25,"Closed") -> Closed
A26: Unique Ventures | B26: PRF_Details_Not Availbale | C26: PRF_Details_Not Availbale | D26: Kinshasa | E26: PRF_Details_Not Availbale | F26: 0 | G26: =IF(AG26="","GRN Not Received",AW26/AG26) -> 1 | H26: =IF(E26="PRF_Details_Not Availbale","PRF Qty Not Available",IF(G26="GRN Not Received","GRN Not Received",--E26*--G26)) -> PRF Qty Not Available | I26: 043/2024 | J26: 45388 | K26: 3000 | L26: 0.56 | M26: =K26*L26 -> 1680 | N26: 0 | O26: 0 | P26: =M26+O26 -> 1680 | Q26: 23-24/108 | R26: 45381 | S26: Pharmax India Pvt Ltd | T26: FG07410 | U26: =IFERROR(VLOOKUP(T26,'item master'!B:C,2,0),"") -> ATARIUM 50MG/5ML (ATACURIUM ) INJ. B/5 AMP. | V26: =K26 -> 3000 | W26: 0 | X26: =L26 -> 0.56 | Y26: =V26*X26 -> 1680 | Z26: 0 | AA26: =Y26+Z26 -> 1680 | AB26: 0.3 | AC26: =Y26*AB26 -> 504 | AD26: =AC26 -> 504 | AE26: 45463 | AF26: EPHCOP17203Y9ZGA | AG26: 2880 | AH26: =AG26 -> 2880 | AJ26: =V26-AG26 -> 120 | AK26: 24-25/311 | AL26: 45621 | AM26: UNIQUE VENTURES | AN26: 0.56 | AO26: =AG26*AN26 -> 1612.8 | AS26: =AO26+AP26+AQ26+AR26 -> 1612.8 | AT26: 071-5484 5781 | AU26: 45624 | AV26: Goods Received at Warehouse | AW26: 2880 | AX26: 24KIN/IGRN000343 | AY26: 45654 | AZ26: 75 | BA26: =AD26+AZ26 -> 579 | BB26: 0 | BC26: 0 | BD26: =IF(AK26>0,BA26+BB26+BC26,"0") -> 579 | BE26: =BA26-BD26 -> 0 | BF26: 0 | BG26: =BE26-BF26 -> 0 | BH26: =AS26-BD26 -> 1033.8 | BI26: =BH26 -> 1033.8 | BJ26: 45765 | BK26: SWIFT COPY NOT AVAILABLE | BO26: =BI26+BL26 -> 1033.8 | BP26: =BH26-BO26 -> 0 | BQ26: =IF(ROUND(BG26,2)>0,"Advance With Supplier",IF(ROUND(BP26,2)>0,"Payable Balance Supplier","Fully Paid")) -> Fully Paid | BS26: =IF(AX26<>"","Closed","Open") -> Closed | BT26: =IF(BS26="Open",TODAY()-J26,"Closed") -> Closed
A27: Unique Ventures | B27: PRF_Details_Not Availbale | C27: PRF_Details_Not Availbale | D27: Kinshasa | E27: PRF_Details_Not Availbale | F27: 0 | G27: =IF(AG27="","GRN Not Received",AW27/AG27) -> 1 | H27: =IF(E27="PRF_Details_Not Availbale","PRF Qty Not Available",IF(G27="GRN Not Received","GRN Not Received",--E27*--G27)) -> PRF Qty Not Available | I27: 043/2024 | J27: 45388 | K27: 10000 | L27: 0.2 | M27: =K27*L27 -> 2000 | N27: 0 | O27: 0 | P27: =M27+O27 -> 2000 | Q27: 23-24/108 | R27: 45381 | S27: Pharmax India Pvt Ltd | T27: FG07412 | U27: =IFERROR(VLOOKUP(T27,'item master'!B:C,2,0),"") -> DICQUE AQUA 75MG/ML (DICLOFÉNAC ) INJ. B/5 AMP | V27: =K27 -> 10000 | W27: 0 | X27: =L27 -> 0.2 | Y27: =V27*X27 -> 2000 | Z27: 0 | AA27: =Y27+Z27 -> 2000 | AB27: 0.3 | AC27: =Y27*AB27 -> 600 | AD27: =AC27 -> 600 | AE27: 45463 | AF27: EPHCOP17203Y9ZGA | AG27: 8570 | AH27: =AG27 -> 8570 | AJ27: =V27-AG27 -> 1430 | AK27: 24-25/322 | AL27: 45625 | AM27: UNIQUE VENTURES | AN27: =X27 -> 0.2 | AO27: =AG27*AN27 -> 1714 | AS27: =AO27+AP27+AQ27+AR27 -> 1714 | AT27: AMC2336146 | AU27: 45667 | AV27: Goods Received at Warehouse | AW27: 8570 | AX27: 25KIN/IGRN000021 | AY27: 45721 | AZ27: -13.5 | BA27: =AD27+AZ27 -> 586.5 | BB27: 0 | BC27: 0 | BD27: =IF(AK27>0,BA27+BB27+BC27,"0") -> 586.5 | BE27: =BA27-BD27 -> 0 | BF27: 0 | BG27: =BE27-BF27 -> 0 | BH27: =AS27-BD27 -> 1127.5 | BI27: =BH27 -> 1127.5 | BJ27: 45765 | BK27: SWIFT COPY NOT AVAILABLE | BO27: =BI27+BL27 -> 1127.5 | BP27: =BH27-BO27 -> 0 | BQ27: =IF(ROUND(BG27,2)>0,"Advance With Supplier",IF(ROUND(BP27,2)>0,"Payable Balance Supplier","Fully Paid")) -> Fully Paid | BS27: =IF(AX27<>"","Closed","Open") -> Closed | BT27: =IF(BS27="Open",TODAY()-J27,"Closed") -> Closed
A28: Unique Ventures | B28: PRF_Details_Not Availbale | C28: PRF_Details_Not Availbale | D28: Kinshasa | E28: PRF_Details_Not Availbale | F28: 0 | G28: =IF(AG28="","GRN Not Received",AW28/AG28) -> 1 | H28: =IF(E28="PRF_Details_Not Availbale","PRF Qty Not Available",IF(G28="GRN Not Received","GRN Not Received",--E28*--G28)) -> PRF Qty Not Available | I28: 043/2024 | J28: 45388 | K28: 10000 | L28: 0.43 | M28: =K28*L28 -> 4300 | N28: 0 | O28: 0 | P28: =M28+O28 -> 4300 | Q28: 23-24/108 | R28: 45381 | S28: Pharmax India Pvt Ltd | T28: FG07419 | U28: =IFERROR(VLOOKUP(T28,'item master'!B:C,2,0),"") -> LABTOL 5MG/ML (LABÉTALOL ) 5ML INJ. B/5 AMP | V28: =K28 -> 10000 | W28: 0 | X28: =L28 -> 0.43 | Y28: =V28*X28 -> 4300 | Z28: 0 | AA28: =Y28+Z28 -> 4300 | AB28: 0.3 | AC28: =Y28*AB28 -> 1290 | AD28: =AC28 -> 1290 | AE28: 45463 | AF28: EPHCOP17203Y9ZGA | AG28: 9250 | AH28: =AG28 -> 9250 | AJ28: =V28-AG28 -> 750 | AK28: 24-25/322 | AL28: 45625 | AM28: UNIQUE VENTURES | AN28: =X28 -> 0.43 | AO28: =AG28*AN28 -> 3977.5 | AS28: =AO28+AP28+AQ28+AR28 -> 3977.5 | AT28: AMC2336146 | AU28: 45667 | AV28: Goods Received at Warehouse | AW28: 9250 | AX28: 25KIN/IGRN000021 | AY28: 45721 | AZ28: -30.6 | BA28: =AD28+AZ28 -> 1259.4 | BB28: 0 | BC28: 0 | BD28: =IF(AK28>0,BA28+BB28+BC28,"0") -> 1259.4 | BE28: =BA28-BD28 -> 0 | BF28: 0 | BG28: =BE28-BF28 -> 0 | BH28: =AS28-BD28 -> 2718.1 | BI28: =BH28 -> 2718.1 | BJ28: 45765 | BK28: SWIFT COPY NOT AVAILABLE | BO28: =BI28+BL28 -> 2718.1 | BP28: =BH28-BO28 -> 0 | BQ28: =IF(ROUND(BG28,2)>0,"Advance With Supplier",IF(ROUND(BP28,2)>0,"Payable Balance Supplier","Fully Paid")) -> Fully Paid | BS28: =IF(AX28<>"","Closed","Open") -> Closed | BT28: =IF(BS28="Open",TODAY()-J28,"Closed") -> Closed
A29: Unique Ventures | B29: PRF_Details_Not Availbale | C29: PRF_Details_Not Availbale | D29: Kinshasa | E29: PRF_Details_Not Availbale | F29: 0 | G29: =IF(AG29="","GRN Not Received",AW29/AG29) -> 1 | H29: =IF(E29="PRF_Details_Not Availbale","PRF Qty Not Available",IF(G29="GRN Not Received","GRN Not Received",--E29*--G29)) -> PRF Qty Not Available | I29: 043/2024 | J29: 45388 | K29: 10000 | L29: 0.3 | M29: =K29*L29 -> 3000 | N29: 0 | O29: 0 | P29: =M29+O29 -> 3000 | Q29: 23-24/108 | R29: 45381 | S29: Pharmax India Pvt Ltd | T29: FG07422 | U29: =IFERROR(VLOOKUP(T29,'item master'!B:C,2,0),"") -> UNISTIGMINE 0.5MG/ML (NÉOSTIGMINE) INJ. B/5 AMP | V29: =K29 -> 10000 | W29: 0 | X29: =L29 -> 0.3 | Y29: =V29*X29 -> 3000 | Z29: 0 | AA29: =Y29+Z29 -> 3000 | AB29: 0.3 | AC29: =Y29*AB29 -> 900 | AD29: =AC29 -> 900 | AE29: 45463 | AF29: EPHCOP17203Y9ZGA | AG29: 10360 | AH29: =AG29 -> 10360 | AJ29: =V29-AG29 -> -360 | AK29: 24-25/322 | AL29: 45625 | AM29: UNIQUE VENTURES | AN29: =X29 -> 0.3 | AO29: =AG29*AN29 -> 3108 | AS29: =AO29+AP29+AQ29+AR29 -> 3108 | AT29: AMC2336146 | AU29: 45667 | AV29: Goods Received at Warehouse | AW29: 10360 | AX29: 25KIN/IGRN000021 | AY29: 45721 | AZ29: -660 | BA29: =AD29+AZ29 -> 240 | BB29: 0 | BC29: 0 | BD29: =IF(AK29>0,BA29+BB29+BC29,"0") -> 240 | BE29: =BA29-BD29 -> 0 | BF29: 0 | BG29: =BE29-BF29 -> 0 | BH29: =AS29-BD29 -> 2868 | BI29: =BH29 -> 2868 | BJ29: 45765 | BK29: SWIFT COPY NOT AVAILABLE | BO29: =BI29+BL29 -> 2868 | BP29: =BH29-BO29 -> 0 | BQ29: =IF(ROUND(BG29,2)>0,"Advance With Supplier",IF(ROUND(BP29,2)>0,"Payable Balance Supplier","Fully Paid")) -> Fully Paid | BS29: =IF(AX29<>"","Closed","Open") -> Closed | BT29: =IF(BS29="Open",TODAY()-J29,"Closed") -> Closed
A30: Unique Ventures | B30: PRF_Details_Not Availbale | C30: PRF_Details_Not Availbale | D30: Kinshasa | E30: PRF_Details_Not Availbale | F30: 0 | G30: =IF(AG30="","GRN Not Received",AW30/AG30) -> 1 | H30: =IF(E30="PRF_Details_Not Availbale","PRF Qty Not Available",IF(G30="GRN Not Received","GRN Not Received",--E30*--G30)) -> PRF Qty Not Available | I30: 043/2024 | J30: 45388 | K30: 10000 | L30: 0.2 | M30: =K30*L30 -> 2000 | N30: 0 | O30: 0 | P30: =M30+O30 -> 2000 | Q30: 23-24/108 | R30: 45381 | S30: Pharmax India Pvt Ltd | T30: FG07426 | U30: =IFERROR(VLOOKUP(T30,'item master'!B:C,2,0),"") -> FELOXAM 20MG/ML (PIROXICAM) INJ. B/2AMP | V30: =K30 -> 10000 | W30: 0 | X30: =L30 -> 0.2 | Y30: =V30*X30 -> 2000 | Z30: 0 | AA30: =Y30+Z30 -> 2000 | AB30: 0.3 | AC30: =Y30*AB30 -> 600 | AD30: =AC30 -> 600 | AE30: 45463 | AF30: EPHCOP17203Y9ZGA | AG30: 11085 | AH30: =AG30 -> 11085 | AJ30: =V30-AG30 -> -1085 | AK30: 24-25/436 | AL30: 45695 | AM30: UNIQUE VENTURES | AN30: 0.2 | AO30: =AG30*AN30 -> 2217 | AS30: =AO30+AP30+AQ30+AR30 -> 2217 | AT30: 2515134444 | AV30: Goods Received at Warehouse | AW30: 11085 | AX30: 25KIN1/IGRN000088 | AZ30: 13.77 | BA30: =AD30+AZ30 -> 613.77 | BB30: 0 | BC30: 0 | BD30: =IF(AK30>0,BA30+BB30+BC30,"0") -> 613.77 | BE30: =BA30-BD30 -> 0 | BF30: 0 | BG30: =BE30-BF30 -> 0 | BH30: =AS30-BD30 -> 1603.23 | BI30: =BH30 -> 1603.23 | BJ30: 45765 | BK30: SWIFT COPY NOT AVAILABLE | BO30: =BI30+BL30 -> 1603.23 | BP30: =BH30-BO30 -> 0 | BQ30: =IF(ROUND(BG30,2)>0,"Advance With Supplier",IF(ROUND(BP30,2)>0,"Payable Balance Supplier","Fully Paid")) -> Fully Paid | BS30: =IF(AX30<>"","Closed","Open") -> Closed | BT30: =IF(BS30="Open",TODAY()-J30,"Closed") -> Closed
A31: Unique Ventures | B31: PRF_Details_Not Availbale | C31: PRF_Details_Not Availbale | D31: Kinshasa | E31: PRF_Details_Not Availbale | F31: 0 | G31: =IF(AG31="","GRN Not Received",AW31/AG31) -> 1 | H31: =IF(E31="PRF_Details_Not Availbale","PRF Qty Not Available",IF(G31="GRN Not Received","GRN Not Received",--E31*--G31)) -> PRF Qty Not Available | I31: 043/2024 | J31: 45388 | K31: 3000 | L31: 0.75 | M31: =K31*L31 -> 2250 | N31: 0 | O31: 0 | P31: =M31+O31 -> 2250 | Q31: 23-24/108 | R31: 45381 | S31: Pharmax India Pvt Ltd | T31: FG07417 | U31: =IFERROR(VLOOKUP(T31,'item master'!B:C,2,0),"") -> HALDOQUE 5MG/ML (HALOPÉRIDOLUM) INJ. B/5 AMP | V31: =K31 -> 3000 | W31: 0 | X31: =L31 -> 0.75 | Y31: =V31*X31 -> 2250 | Z31: 0 | AA31: =Y31+Z31 -> 2250 | AB31: 0.3 | AC31: =Y31*AB31 -> 675 | AD31: =AC31 -> 675 | AE31: 45463 | AF31: EPHCOP17203Y9ZGA | AG31: 2580 | AH31: =AG31 -> 2580 | AJ31: =V31-AG31 -> 420 | AK31: 24-25/322 | AL31: 45625 | AM31: UNIQUE VENTURES | AN31: =X31 -> 0.75 | AO31: =AG31*AN31 -> 1935 | AS31: =AO31+AP31+AQ31+AR31 -> 1935 | AT31: AMC2336146 | AU31: 45667 | AV31: Goods Received at Warehouse | AW31: 2580 | AX31: 25KIN/IGRN000021 | AY31: 45721 | AZ31: 30 | BA31: =AD31+AZ31 -> 705 | BB31: 0 | BC31: 0 | BD31: =IF(AK31>0,BA31+BB31+BC31,"0") -> 705 | BE31: =BA31-BD31 -> 0 | BF31: 0 | BG31: =BE31-BF31 -> 0 | BH31: =AS31-BD31 -> 1230 | BI31: =BH31 -> 1230 | BJ31: 45765 | BK31: SWIFT COPY NOT AVAILABLE | BO31: =BI31+BL31 -> 1230 | BP31: =BH31-BO31 -> 0 | BQ31: =IF(ROUND(BG31,2)>0,"Advance With Supplier",IF(ROUND(BP31,2)>0,"Payable Balance Supplier","Fully Paid")) -> Fully Paid | BS31: =IF(AX31<>"","Closed","Open") -> Closed | BT31: =IF(BS31="Open",TODAY()-J31,"Closed") -> Closed
A32: Unique Ventures | B32: PRF_Details_Not Availbale | C32: PRF_Details_Not Availbale | D32: Kinshasa | E32: PRF_Details_Not Availbale | F32: 0 | G32: =IF(AG32="","GRN Not Received",AW32/AG32) -> 1 | H32: =IF(E32="PRF_Details_Not Availbale","PRF Qty Not Available",IF(G32="GRN Not Received","GRN Not Received",--E32*--G32)) -> PRF Qty Not Available | I32: 043/2024 | J32: 45388 | K32: 2000 | L32: 0.89 | M32: =K32*L32 -> 1780 | N32: 0 | O32: 0 | P32: =M32+O32 -> 1780 | Q32: 23-24/108 | R32: 45381 | S32: Pharmax India Pvt Ltd | T32: FG07416 | U32: =IFERROR(VLOOKUP(T32,'item master'!B:C,2,0),"") -> HALDOQUE DECONOAS 50MG/ML (HALOPÉRIDOL) INJ.B/5 AMP | V32: =K32 -> 2000 | W32: 0 | X32: =L32 -> 0.89 | Y32: =V32*X32 -> 1780 | Z32: 0 | AA32: =Y32+Z32 -> 1780 | AB32: 0.3 | AC32: =Y32*AB32 -> 534 | AD32: =AC32 -> 534 | AE32: 45463 | AF32: EPHCOP17203Y9ZGA | AG32: 1660 | AH32: =AG32 -> 1660 | AJ32: =V32-AG32 -> 340 | AK32: 24-25/322 | AL32: 45625 | AM32: UNIQUE VENTURES | AN32: =X32 -> 0.89 | AO32: =AG32*AN32 -> 1477.4 | AS32: =AO32+AP32+AQ32+AR32 -> 1477.4 | AT32: AMC2336146 | AU32: 45667 | AV32: Goods Received at Warehouse | AW32: 1660 | AX32: 25KIN/IGRN000021 | AY32: 45721 | AZ32: 0 | BA32: =AD32+AZ32 -> 534 | BB32: 0 | BC32: 0 | BD32: =IF(AK32>0,BA32+BB32+BC32,"0") -> 534 | BE32: =BA32-BD32 -> 0 | BF32: 0 | BG32: =BE32-BF32 -> 0 | BH32: =AS32-BD32 -> 943.4 | BI32: =BH32 -> 943.4 | BJ32: 45765 | BK32: SWIFT COPY NOT AVAILABLE | BO32: =BI32+BL32 -> 943.4 | BP32: =BH32-BO32 -> 0 | BQ32: =IF(ROUND(BG32,2)>0,"Advance With Supplier",IF(ROUND(BP32,2)>0,"Payable Balance Supplier","Fully Paid")) -> Fully Paid | BS32: =IF(AX32<>"","Closed","Open") -> Closed | BT32: =IF(BS32="Open",TODAY()-J32,"Closed") -> Closed
A33: Unique Ventures | B33: PRF_Details_Not Availbale | C33: PRF_Details_Not Availbale | D33: Kinshasa | E33: PRF_Details_Not Availbale | F33: 0 | G33: =IF(AG33="","GRN Not Received",AW33/AG33) -> 1 | H33: =IF(E33="PRF_Details_Not Availbale","PRF Qty Not Available",IF(G33="GRN Not Received","GRN Not Received",--E33*--G33)) -> PRF Qty Not Available | I33: 043/2024 | J33: 45388 | K33: 5000 | L33: 0.42 | M33: =K33*L33 -> 2100 | N33: 0 | O33: 0 | P33: =M33+O33 -> 2100 | Q33: 23-24/108 | R33: 45381 | S33: Pharmax India Pvt Ltd | T33: FG07421 | U33: =IFERROR(VLOOKUP(T33,'item master'!B:C,2,0),"") -> SOLU-PREDNOL 40MG (METHYLPREDNISOLONE) INJ.B/1 VIAL+SOLVENT 2ML | V33: =K33 -> 5000 | W33: 0 | X33: =L33 -> 0.42 | Y33: =V33*X33 -> 2100 | Z33: 0 | AA33: =Y33+Z33 -> 2100 | AB33: 0.3 | AC33: =Y33*AB33 -> 630 | AD33: =AC33 -> 630 | AE33: 45463 | AF33: EPHCOP17203Y9ZGA | AG33: 4800 | AH33: =AG33 -> 4800 | AJ33: =V33-AG33 -> 200 | AK33: 24-25/322 | AL33: 45625 | AM33: UNIQUE VENTURES | AN33: 0.42 | AO33: =AG33*AN33 -> 2016 | AS33: =AO33+AP33+AQ33+AR33 -> 2016 | AT33: AMC2336146 | AU33: 45667 | AV33: Goods Received at Warehouse | AW33: 4800 | AX33: 25KIN/IGRN000021 | AY33: 45721 | AZ33: 0 | BA33: =AD33+AZ33 -> 630 | BB33: 0 | BC33: 0 | BD33: =IF(AK33>0,BA33+BB33+BC33,"0") -> 630 | BE33: =BA33-BD33 -> 0 | BF33: 0 | BG33: =BE33-BF33 -> 0 | BH33: =AS33-BD33 -> 1386 | BI33: =BH33 -> 1386 | BJ33: 45765 | BK33: SWIFT COPY NOT AVAILABLE | BO33: =BI33+BL33 -> 1386 | BP33: =BH33-BO33 -> 0 | BQ33: =IF(ROUND(BG33,2)>0,"Advance With Supplier",IF(ROUND(BP33,2)>0,"Payable Balance Supplier","Fully Paid")) -> Fully Paid | BS33: =IF(AX33<>"","Closed","Open") -> Closed | BT33: =IF(BS33="Open",TODAY()-J33,"Closed") -> Closed
A34: Unique Ventures | B34: PRF_Details_Not Availbale | C34: PRF_Details_Not Availbale | D34: Kinshasa | E34: PRF_Details_Not Availbale | F34: 0 | G34: =IF(AG34="","GRN Not Received",AW34/AG34) -> 1 | H34: =IF(E34="PRF_Details_Not Availbale","PRF Qty Not Available",IF(G34="GRN Not Received","GRN Not Received",--E34*--G34)) -> PRF Qty Not Available | I34: 043/2024 | J34: 45388 | K34: 5000 | L34: 0.83 | M34: =K34*L34 -> 4150 | N34: 0 | O34: 0 | P34: =M34+O34 -> 4150 | Q34: 23-24/108 | R34: 45381 | S34: Pharmax India Pvt Ltd | T34: FG07420 | U34: =IFERROR(VLOOKUP(T34,'item master'!B:C,2,0),"") -> SOLU-PREDNOL 125MG (MÉTHYLPREDNISOLONE) INJ.B/1 VIAL + SOLVENT 2ML | V34: =K34 -> 5000 | W34: 0 | X34: =L34 -> 0.83 | Y34: =V34*X34 -> 4150 | Z34: 0 | AA34: =Y34+Z34 -> 4150 | AB34: 0.3 | AC34: =Y34*AB34 -> 1245 | AD34: =AC34 -> 1245 | AE34: 45463 | AF34: EPHCOP17203Y9ZGA | AG34: 4000 | AH34: =AG34 -> 4000 | AJ34: =V34-AG34 -> 1000 | AK34: 24-25/322 | AL34: 45625 | AM34: UNIQUE VENTURES | AN34: 0.83 | AO34: =AG34*AN34 -> 3320 | AS34: =AO34+AP34+AQ34+AR34 -> 3320 | AT34: AMC2336146 | AU34: 45667 | AV34: Goods Received at Warehouse | AW34: 4000 | AX34: 25KIN/IGRN000021 | AY34: 45721 | AZ34: 0 | BA34: =AD34+AZ34 -> 1245 | BB34: 0 | BC34: 0 | BD34: =IF(AK34>0,BA34+BB34+BC34,"0") -> 1245 | BE34: =BA34-BD34 -> 0 | BF34: 0 | BG34: =BE34-BF34 -> 0 | BH34: =AS34-BD34 -> 2075 | BI34: =BH34 -> 2075 | BJ34: 45765 | BK34: SWIFT COPY NOT AVAILABLE | BO34: =BI34+BL34 -> 2075 | BP34: =BH34-BO34 -> 0 | BQ34: =IF(ROUND(BG34,2)>0,"Advance With Supplier",IF(ROUND(BP34,2)>0,"Payable Balance Supplier","Fully Paid")) -> Fully Paid | BS34: =IF(AX34<>"","Closed","Open") -> Closed | BT34: =IF(BS34="Open",TODAY()-J34,"Closed") -> Closed
A35: Unique Ventures | B35: PRF_Details_Not Availbale | C35: PRF_Details_Not Availbale | D35: Kinshasa | E35: PRF_Details_Not Availbale | F35: 0 | G35: =IF(AG35="","GRN Not Received",AW35/AG35) -> 1 | H35: =IF(E35="PRF_Details_Not Availbale","PRF Qty Not Available",IF(G35="GRN Not Received","GRN Not Received",--E35*--G35)) -> PRF Qty Not Available | I35: 043/2024 | J35: 45388 | K35: 20000 | L35: 0.3 | M35: =K35*L35 -> 6000 | N35: 0 | O35: 0 | P35: =M35+O35 -> 6000 | Q35: 23-24/108 | R35: 45381 | S35: Pharmax India Pvt Ltd | T35: FG07414 | U35: =IFERROR(VLOOKUP(T35,'item master'!B:C,2,0),"") -> SPASMOSTOP 40MG/2ML ( DROTAVÉRINE ) INJ. B/5 AMP | V35: =K35 -> 20000 | W35: 0 | X35: =L35 -> 0.3 | Y35: =V35*X35 -> 6000 | Z35: 0 | AA35: =Y35+Z35 -> 6000 | AB35: 0.3 | AC35: =Y35*AB35 -> 1800 | AD35: =AC35 -> 1800 | AE35: 45463 | AF35: EPHCOP17203Y9ZGA | AG35: 20340 | AH35: =AG35 -> 20340 | AJ35: =V35-AG35 -> -340 | AK35: 24-25/192 | AL35: 45537 | AM35: UNIQUE VENTURES | AN35: 0.3 | AO35: =AG35*AN35 -> 6102 | AS35: =AO35+AP35+AQ35+AR35 -> 6102 | AT35: 244450371 | AV35: Goods Received at Warehouse | AW35: 20340 | AX35: 24KIN/IGRN000302 | AY35: 45608 | AZ35: 0 | BA35: =AD35+AZ35 -> 1800 | BB35: 0 | BC35: 30.6 | BD35: =IF(AK35>0,BA35+BB35+BC35,"0") -> 1830.6 | BE35: =BA35-BD35 -> -30.6 | BF35: -30.6 | BG35: =BE35-BF35 -> 9.2370556e-14 | BH35: =AS35-BD35 -> 4271.4 | BI35: =BH35 -> 4271.4 | BJ35: 45586 | BK35: EPHCOP29504UC6MI | BO35: =BI35+BL35 -> 4271.4 | BP35: =BH35-BO35 -> 0 | BQ35: =IF(ROUND(BG35,2)>0,"Advance With Supplier",IF(ROUND(BP35,2)>0,"Payable Balance Supplier","Fully Paid")) -> Fully Paid | BS35: =IF(AX35<>"","Closed","Open") -> Closed | BT35: =IF(BS35="Open",TODAY()-J35,"Closed") -> Closed
A36: Unique Ventures | B36: 1293.24 | C36: 45381 | D36: Kinshasa | E36: 500000 | F36: Pack of 6 Amps | G36: =IF(AG36="","GRN Not Received",AW36/AG36) -> 1 | H36: =IF(E36="PRF_Details_Not Availbale","PRF Qty Not Available",IF(G36="GRN Not Received","GRN Not Received",--E36*--G36)) -> 500000 | I36: 043/2024 | J36: 45388 | K36: 500000 | L36: 0.2 | M36: =K36*L36 -> 100000 | N36: 0 | O36: 0 | P36: =M36+O36 -> 100000 | Q36: 23-24/112 | R36: 45381 | S36: Pharmax India Pvt Ltd | T36: FG03621 | U36: =IFERROR(VLOOKUP(T36,'item master'!B:C,2,0),"") -> ARTEMETHER 80MG/ML INJ B/6AMP | V36: =K36 -> 500000 | W36: 0 | X36: =L36 -> 0.2 | Y36: =V36*X36 -> 100000 | Z36: 0 | AA36: =Y36+Z36 -> 100000 | AB36: 0.3 | AC36: =Y36*AB36 -> 30000 | AD36: =AC36 -> 30000 | AE36: 45463 | AF36: EPHCOP17203Y9ZGA | AG36: 511000 | AH36: =AG36 -> 511000 | AJ36: =V36-AG36 -> -11000 | AK36: 24-25/078 | AL36: 45457 | AM36: UNIQUE VENTURES | AN36: 0.2 | AO36: =AG36*AN36 -> 102200 | AS36: =AO36+AP36+AQ36+AR36 -> 102200 | AT36: AMC2229366 | AU36: 45500 | AV36: Goods Received at Warehouse | AW36: 511000 | AX36: 24KIN/IGRN000234 | AY36: 45544 | AZ36: 0 | BA36: =AD36+AZ36 -> 30000 | BB36: 0 | BC36: 660 | BD36: =IF(AK36>0,BA36+BB36+BC36,"0") -> 30660 | BE36: =BA36-BD36 -> -660 | BF36: -660 | BG36: =BE36-BF36 -> 0 | BH36: =AS36-BD36 -> 71540 | BI36: =BH36 -> 71540 | BJ36: 45500 | BK36: EPHCOP209047ZI1N | BO36: =BI36+BL36 -> 71540 | BP36: =BH36-BO36 -> 0 | BQ36: =IF(ROUND(BG36,2)>0,"Advance With Supplier",IF(ROUND(BP36,2)>0,"Payable Balance Supplier","Fully Paid")) -> Fully Paid | BS36: =IF(AX36<>"","Closed","Open") -> Closed | BT36: =IF(BS36="Open",TODAY()-J36,"Closed") -> Closed
A37: Unique Ventures | B37: 1384.24 | C37: 45553 | D37: Kinshasa | E37: 4000 | F37: Pack of 10 Amps | G37: =IF(AG37="","GRN Not Received",AW37/AG37) -> 1 | H37: =IF(E37="PRF_Details_Not Availbale","PRF Qty Not Available",IF(G37="GRN Not Received","GRN Not Received",--E37*--G37)) -> 4000 | I37: 0136/2024 | J37: 45555 | K37: 4000 | L37: 0.74 | M37: =K37*L37 -> 2960 | N37: 0 | O37: 0 | P37: =M37+O37 -> 2960 | Q37: 24-25/018 | R37: 45553 | S37: Pharmax India Pvt Ltd | T37: FG00537 | U37: =IFERROR(VLOOKUP(T37,'item master'!B:C,2,0),"") -> CAFEINE B/10AMP | V37: 4000 | W37: 0 | X37: 0.74 | Y37: =V37*X37 -> 2960 | Z37: 0 | AA37: =Y37+Z37 -> 2960 | AB37: 0.3 | AC37: =Y37*AB37 -> 888 | AD37: =AC37 -> 888 | AE37: 45568 | AF37: EPHCOP27704Q5SYK | AG37: 3090 | AH37: =AG37 -> 3090 | AJ37: =V37-AG37 -> 910 | AK37: 24-25/387 | AL37: 45668 | AM37: UNIQUE VENTURES | AN37: 0.74 | AO37: =AG37*AN37 -> 2286.6 | AS37: =AO37+AP37+AQ37+AR37 -> 2286.6 | AT37: AMC2353209 | AU37: 45700 | AV37: Goods Received at Warehouse | AW37: 3090 | AX37: 25KIN1/IGRN000048 | AY37: 45747 | AZ37: 0 | BA37: =AD37+AZ37 -> 888 | BB37: 0 | BC37: 0 | BD37: =IF(AK37>0,BA37+BB37+BC37,"0") -> 888 | BE37: =BA37-BD37 -> 0 | BF37: 0 | BG37: =BE37-BF37 -> 0 | BH37: =AS37-BD37 -> 1398.6 | BI37: =BH37 -> 1398.6 | BJ37: 45765 | BK37: SWIFT COPY NOT AVAILABLE | BO37: =BI37+BL37 -> 1398.6 | BP37: =BH37-BO37 -> 0 | BQ37: =IF(ROUND(BG37,2)>0,"Advance With Supplier",IF(ROUND(BP37,2)>0,"Payable Balance Supplier","Fully Paid")) -> Fully Paid | BS37: =IF(AX37<>"","Closed","Open") -> Closed | BT37: =IF(BS37="Open",TODAY()-J37,"Closed") -> Closed
